Workbook
Name NR_COMMERCIAL_SCENARIO_ID: COMMERCIAL_SCENARIO!$A$2:$A$5000
Name NR_COMPONENT_ID: COMPONENT!$A$2:$A$5000
Name NR_COMPONENT_MATERIAL_ID: COMPONENT_MATERIAL!$A$2:$A$5000
Name NR_COMPONENT_TYPE_ID: LKP_COMPONENT_TYPE!$A$2:$A$5000
Name NR_COUNTRY_ID: LKP_COUNTRY!$A$2:$A$5000
Name NR_CUSTOMER_ID: CUSTOMER!$A$2:$A$5000
Name NR_DECLARATION_OF_CONFORMITY_ID: DECLARATION_OF_CONFORMITY!$A$2:$A$5000
Name NR_DOCUMENT_ID: DOCUMENT_LIBRARY!$A$2:$A$5000
Name NR_DOCUMENT_LINK_ID: DOCUMENT_LINK!$A$2:$A$5000
Name NR_DOCUMENT_TYPE_ID: LKP_DOCUMENT_TYPE!$A$2:$A$5000
Name NR_INCOTERM_ID: LKP_INCOTERM!$A$2:$A$5000
Name NR_INFO_KEY: SYS_WORKBOOK_INFO!$A$2:$A$5000
Name NR_LEGAL_ENTITY_ID: LEGAL_ENTITY!$A$2:$A$5000
Name NR_LINE_ROLE_ID: LKP_LINE_ROLE!$A$2:$A$5000
Name NR_MATERIAL_FAMILY_ID: LKP_MATERIAL_FAMILY!$A$2:$A$5000
Name NR_MATERIAL_ID: LKP_MATERIAL!$A$2:$A$5000
Name NR_OWNERSHIP_TYPE_ID: LKP_OWNERSHIP_TYPE!$A$2:$A$5000
Name NR_PACKAGING_CONFIGURATION_ID: PACKAGING_CONFIGURATION!$A$2:$A$5000
Name NR_PACKAGING_CONFIGURATION_LINE_ID: PACKAGING_CONFIGURATION_LINE!$A$2:$A$5000
Name NR_PACKAGING_FUNCTION_ID: LKP_PACKAGING_FUNCTION!$A$2:$A$5000
Name NR_PACKAGING_LEVEL_ID: LKP_PACKAGING_LEVEL!$A$2:$A$5000
Name NR_PARAMETER_ID: SYS_PARAMETER!$A$2:$A$5000
Name NR_PERSON_ID: PERSON!$A$2:$A$5000
Name NR_PLANT_ID: PLANT!$A$2:$A$5000
Name NR_PPWR_MATERIAL_CATEGORY_ID: LKP_PPWR_MATERIAL_CATEGORY!$A$2:$A$5000
Name NR_PRODUCT_CATEGORY_ID: LKP_PRODUCT_CATEGORY!$A$2:$A$5000
Name NR_PRODUCT_ID: PRODUCT!$A$2:$A$5000
Name NR_RECYCLABILITY_CLASS_ID: LKP_RECYCLABILITY_CLASS!$A$2:$A$5000
Name NR_SCENARIO_TYPE_ID: LKP_SCENARIO_TYPE!$A$2:$A$5000
Name NR_SHIPMENT_ID: SHIPMENT!$A$2:$A$5000
Name NR_SHIPMENT_LINE_ID: SHIPMENT_LINE!$A$2:$A$5000
Name NR_STATEMENT_ID: STATEMENT!$A$2:$A$5000
Name NR_STATEMENT_LINE_ID: STATEMENT_LINE!$A$2:$A$5000
Name NR_STATEMENT_SHIPMENT_ID: STATEMENT_SHIPMENT!$A$2:$A$5000
Name NR_STATEMENT_TYPE_ID: LKP_STATEMENT_TYPE!$A$2:$A$5000
Name NR_STATUS_ID: LKP_STATUS!$A$2:$A$5000
Name NR_SUPPLIER_ID: SUPPLIER!$A$2:$A$5000
Name NR_TECHNICAL_FILE_ID: TECHNICAL_FILE!$A$2:$A$5000
Name NR_TRANSPORT_CONFIGURATION_ID: TRANSPORT_CONFIGURATION!$A$2:$A$5000
Name NR_TRANSPORT_CONFIGURATION_LINE_ID: TRANSPORT_CONFIGURATION_LINE!$A$2:$A$5000
Name NR_TRANSPORT_MODE_ID: LKP_TRANSPORT_MODE!$A$2:$A$5000
Name NR_TRANSPORT_UNIT_TYPE_ID: LKP_TRANSPORT_UNIT_TYPE!$A$2:$A$5000
Name NR_UOM_ID: LKP_UOM!$A$2:$A$5000

Sheet 00_HOME

Sheet NAVIGATION

Sheet SEARCH
B7: SEARCH BY · Packaging Set / Configuration ID
B8: ⌕
B10: Results update automatically as you type · Examples: ST-051-STD-01 · CNT-20-STD-01 · IND-24V-01
B12: RESULTS
B13: =IF($C$8="","Enter a Packaging Set or Configuration ID to view controlled data.","") -> Enter a Packaging Set or Configuration ID to view controlled data.
B14: Configuration ID | D14: =IF($C$8="","",IFERROR(_xlfn.XLOOKUP($C$8,PACKAGING_CONFIGURATIONS!A:A,PACKAGING_CONFIGURATIONS!B:B),"Not found — use AutoFilter on Document Center"))
B15: Family | D15: =IF($C$8="","",IFERROR(_xlfn.XLOOKUP($C$8,PACKAGING_CONFIGURATIONS!A:A,PACKAGING_CONFIGURATIONS!D:D),"Not found — use AutoFilter on Document Center"))
B16: Source Configuration ID | D16: =IF($C$8="","",IFERROR(_xlfn.XLOOKUP($C$8,PACKAGING_CONFIGURATIONS!A:A,PACKAGING_CONFIGURATIONS!C:C),"Not found — use AutoFilter on Document Center"))
B17: Technical File ID | D17: =IF($C$8="","",IFERROR(_xlfn.XLOOKUP($C$8,PACKAGING_CONFIGURATIONS!A:A,PACKAGING_CONFIGURATIONS!K:K),"Not found — use AutoFilter on Document Center"))
B18: Packaging Tare kg | D18: =IF($C$8="","",IFERROR(_xlfn.XLOOKUP($C$8,PACKAGING_CONFIGURATIONS!A:A,PACKAGING_CONFIGURATIONS!H:H),"Not found — use AutoFilter on Document Center"))
B19: Document Pack Status | D19: 988 / 988 LINKED · Rev.00

Sheet PACKAGING_CONFIGURATIONS
A1: ← HOME | B1: NAVIGATION | C1: SEARCH | D1: DOCUMENT CENTER | H1: REV.00
A2: PACKAGING CONFIGURATIONS
A3: Final packaging set register — 247 controlled configurations
A4: 247 · RECORDS | C4: 00 · REV | E4: READY · STATUS | G4: YES · LINKED
A6: Packaging Set Code | B6: Final Configuration ID | C6: Source Configuration ID | D6: Family | E6: Packaging Description | F6: Variant Basis TR | G6: Variant Basis EN | H6: Packaging Tare kg | I6: Product Count | J6: BOM Line Count | K6: Technical File | L6: DoC | M6: Label | N6: Statement
A7: CNT-20-EUR-01 | B7: IA-CNT-20-EUR-01 | C7: IA-CNT-20-EUR | D7: CONTAINER | E7: Container loading | OSB (5501806): 11 adet | Separatör (4000130): 10 adet | F7: Container loading | OSB (5501806): 11 adet | Separatör (4000130): 10 adet | G7: Container loading | OSB (5501806): 11 pcs | Separator (4000130): 10 pcs | H7: 83.06 | I7: 0 | J7: 8 | K7: IA-PPWR-TF-CNT-20-EUR-01-R00 | L7: IA-PPWR-DOC-CNT-20-EUR-01-R00 | M7: IA-PPWR-LBL-CNT-20-EUR-01-R00 | N7: IA-PPWR-STM-CNT-20-EUR-01-R00
A8: CNT-20-STD-01 | B8: IA-CNT-20-STD-01 | C8: IA-CNT-20-STD | D8: CONTAINER | E8: Container loading | OSB (5501805): 10 adet | Separatör (4000130): 10 adet | F8: Container loading | OSB (5501805): 10 adet | Separatör (4000130): 10 adet | G8: Container loading | OSB (5501805): 10 pcs | Separator (4000130): 10 pcs | H8: 78.06 | I8: 0 | J8: 8 | K8: IA-PPWR-TF-CNT-20-STD-01-R00 | L8: IA-PPWR-DOC-CNT-20-STD-01-R00 | M8: IA-PPWR-LBL-CNT-20-STD-01-R00 | N8: IA-PPWR-STM-CNT-20-STD-01-R00
A9: CNT-40-IND-01 | B9: IA-CNT-40-IND-01 | C9: IA-CNT-40-IND | D9: CONTAINER | E9: Container loading | Hava yastığı (5500759): 26 adet | Bağlama halatı (5500762): 12 m | F9: Container loading | Hava yastığı (5500759): 26 adet | Bağlama halatı (5500762): 12 m | G9: Container loading | Air dunnage (5500759): 26 pcs | Lashing rope (5500762): 12 m | H9: 12.76 | I9: 0 | J9: 5 | K9: IA-PPWR-TF-CNT-40-IND-01-R00 | L9: IA-PPWR-DOC-CNT-40-IND-01-R00 | M9: IA-PPWR-LBL-CNT-40-IND-01-R00 | N9: IA-PPWR-STM-CNT-40-IND-01-R00
A10: CNT-DE-HAM-01 | B10: IA-CNT-DE-HAM-01 | C10: IA-CNT-DE-HAMBURG | D10: CONTAINER | E10: Container loading | Sabitleme Tahtası ( 206×9×9 ) (Hamburg): 2 adet | F10: Container loading | Sabitleme Tahtası ( 206×9×9 ) (Hamburg): 2 adet | G10: Container loading | Sabitleme Tahtası ( 206×9×9 ) (Hamburg): 2 pcs | H10: 194 | I10: 0 | J10: 3 | K10: IA-PPWR-TF-CNT-DE-HAM-01-R00 | L10: IA-PPWR-DOC-CNT-DE-HAM-01-R00 | M10: IA-PPWR-LBL-CNT-DE-HAM-01-R00 | N10: IA-PPWR-STM-CNT-DE-HAM-01-R00
A11: IND-24V-01 | B11: IA-IND-24V-01 | C11: IA-IND-24V | D11: INDUSTRIAL | E11: 24V | Palet (4001005): 1 adet | F11: 24V | Palet (4001005): 1 adet | G11: 24V | Pallet (4001005): 1 pc | H11: 27.388 | I11: 0 | J11: 6 | K11: IA-PPWR-TF-IND-24V-01-R00 | L11: IA-PPWR-DOC-IND-24V-01-R00 | M11: IA-PPWR-LBL-IND-24V-01-R00 | N11: IA-PPWR-STM-IND-24V-01-R00
A12: IND-48V-01 | B12: IA-IND-48V-01 | C12: IA-IND-48V | D12: INDUSTRIAL | E12: 48V | Palet (4001005): 1 adet | F12: 48V | Palet (4001005): 1 adet | G12: 48V | Pallet (4001005): 1 pc | H12: 27.5767 | I12: 0 | J12: 6 | K12: IA-PPWR-TF-IND-48V-01-R00 | L12: IA-PPWR-DOC-IND-48V-01-R00 | M12: IA-PPWR-LBL-IND-48V-01-R00 | N12: IA-PPWR-STM-IND-48V-01-R00
A13: IND-80V-01 | B13: IA-IND-80V-01 | C13: IA-IND-80V | D13: INDUSTRIAL | E13: 80V | Palet (4000973): 1 adet | F13: 80V | Palet (4000973): 1 adet | G13: 80V | Pallet (4000973): 1 pc | H13: 32.63147 | I13: 0 | J13: 6 | K13: IA-PPWR-TF-IND-80V-01-R00 | L13: IA-PPWR-DOC-IND-80V-01-R00 | M13: IA-PPWR-LBL-IND-80V-01-R00 | N13: IA-PPWR-STM-IND-80V-01-R00
A14: ST-012-EUR-01 | B14: IA-ST-012-EUR-01 | C14: IA-ST-CFG-0004 | D14: STARTER | E14: C | Palet (4000038): 1 adet | Köşebent (4000590): 4 adet | F14: C | Palet (4000038): 1 adet | Köşebent (4000590): 4 adet | G14: C | Pallet (4000038): 1 pc | Edge protector (4000590): 4 pcs | H14: 29.326 | I14: 1 | J14: 7 | K14: IA-PPWR-TF-ST-012-EUR-01-R00 | L14: IA-PPWR-DOC-ST-012-EUR-01-R00 | M14: IA-PPWR-LBL-ST-012-EUR-01-R00 | N14: IA-PPWR-STM-ST-012-EUR-01-R00
A15: ST-012-EUR-02 | B15: IA-ST-012-EUR-02 | C15: IA-ST-CFG-0005 | D15: STARTER | E15: L6 | Palet (4000038): 1 adet | Köşebent (4000590): 4 adet | F15: L6 | Palet (4000038): 1 adet | Köşebent (4000590): 4 adet | G15: L6 | Pallet (4000038): 1 pc | Edge protector (4000590): 4 pcs | H15: 27.526 | I15: 1 | J15: 6 | K15: IA-PPWR-TF-ST-012-EUR-02-R00 | L15: IA-PPWR-DOC-ST-012-EUR-02-R00 | M15: IA-PPWR-LBL-ST-012-EUR-02-R00 | N15: IA-PPWR-STM-ST-012-EUR-02-R00
A16: ST-012-EUR-03 | B16: IA-ST-012-EUR-03 | C16: IA-ST-CFG-0006 | D16: STARTER | E16: C | Palet (4000038): 1 adet | Köşebent (4000590): 2 adet | F16: C | Palet (4000038): 1 adet | Köşebent (4000590): 2 adet | G16: C | Pallet (4000038): 1 pc | Edge protector (4000590): 2 pcs | H16: 29.0392 | I16: 2 | J16: 7 | K16: IA-PPWR-TF-ST-012-EUR-03-R00 | L16: IA-PPWR-DOC-ST-012-EUR-03-R00 | M16: IA-PPWR-LBL-ST-012-EUR-03-R00 | N16: IA-PPWR-STM-ST-012-EUR-03-R00
A17: ST-018-EUR-01 | B17: IA-ST-018-EUR-01 | C17: IA-ST-CFG-0012 | D17: STARTER | E17: C | Palet (4000038): 1 adet | Köşebent (4001160): 4 adet | F17: C | Palet (4000038): 1 adet | Köşebent (4001160): 4 adet | G17: C | Pallet (4000038): 1 pc | Edge protector (4001160): 4 pcs | H17: 32.434 | I17: 1 | J17: 9 | K17: IA-PPWR-TF-ST-018-EUR-01-R00 | L17: IA-PPWR-DOC-ST-018-EUR-01-R00 | M17: IA-PPWR-LBL-ST-018-EUR-01-R00 | N17: IA-PPWR-STM-ST-018-EUR-01-R00
A18: ST-018-EUR-02 | B18: IA-ST-018-EUR-02 | C18: IA-ST-CFG-0013 | D18: STARTER | E18: C | Palet (4000038): 1 adet | Köşebent (4000590): 4 adet | F18: C | Palet (4000038): 1 adet | Köşebent (4000590): 4 adet | G18: C | Pallet (4000038): 1 pc | Edge protector (4000590): 4 pcs | H18: 30.194 | I18: 4 | J18: 7 | K18: IA-PPWR-TF-ST-018-EUR-02-R00 | L18: IA-PPWR-DOC-ST-018-EUR-02-R00 | M18: IA-PPWR-LBL-ST-018-EUR-02-R00 | N18: IA-PPWR-STM-ST-018-EUR-02-R00
... A253: ST-120-STD-03 | B253: IA-ST-120-STD-03 | C253: IA-ST-CFG-0286 | D253: STARTER | E253: NS40 | Palet (4000037): 1 adet | Shrink film (4001177): 0.597 kg | F253: NS40 | Palet (4000037): 1 adet | Shrink film (4001177): 0.597 kg | G253: NS40 | Pallet (4000037): 1 pc | Shrink film (4001177): 0.597 kg | H253: 28.649 | I253: 4 | J253: 7 | K253: IA-PPWR-TF-ST-120-STD-03-R00 | L253: IA-PPWR-DOC-ST-120-STD-03-R00 | M253: IA-PPWR-LBL-ST-120-STD-03-R00 | N253: IA-PPWR-STM-ST-120-STD-03-R00

Sheet PRODUCT_MASTER
A1: ← HOME | B1: NAVIGATION | C1: SEARCH | D1: DOCUMENT CENTER | H1: REV.00
A2: PRODUCT MASTER
A3: Products linked to packaging configurations
A4: 2046 · RECORDS | C4: 00 · REV | E4: READY · STATUS | G4: YES · LINKED
A6: Product Code | B6: Technical Description | C6: Category | D6: Mapped Packaging Set Code | E6: Configuration ID | F6: Source Configuration ID | G6: Packaging Tare | H6: Document Pack Status
A7: 1000069 | B7: AKÜ,C-FLAT,DK,200AH,İNCİ SUPRA SENTOR | C7: 1 | D7: ST-021-STD-03 | E7: IA-ST-021-STD-03 | F7: IA-ST-CFG-0023 | G7: 31.8252 | H7: 988-pack GENERATED
A8: 1000441 | B8: AKÜ,A-FLAT,DK,120AH,EAS PRIDE,İÇ PYS | C8: 1 | D8: ST-030-STD-08 | E8: IA-ST-030-STD-08 | F8: IA-ST-CFG-0054 | G8: 31.4124 | H8: 988-pack GENERATED
A9: 1000442 | B9: AKÜ,A-FLAT,DK,135AH,EAS PRIDE,İÇ PYS | C9: 1 | D9: ST-030-STD-08 | E9: IA-ST-030-STD-08 | F9: IA-ST-CFG-0054 | G9: 31.4124 | H9: 988-pack GENERATED
A10: 1000445 | B10: AKÜ,B-FLAT,DK,180AH,EAS PRIDE,İÇ PYS | C10: 1 | D10: ST-030-STD-09 | E10: IA-ST-030-STD-09 | F10: IA-ST-CFG-0055 | G10: 32.1024 | H10: 988-pack GENERATED
A11: 1000448 | B11: AKÜ,C-FLAT,DK,200AH,EAS PRIDE,İÇ PYS | C11: 1 | D11: ST-021-STD-04 | E11: IA-ST-021-STD-04 | F11: IA-ST-CFG-0024 | G11: 31.5384 | H11: 988-pack GENERATED
A12: 1000890 | B12: AKÜ,A-FLAT,DK,120AH,İNCİ SUPRA SENTOR | C12: 1 | D12: ST-030-STD-05 | E12: IA-ST-030-STD-05 | F12: IA-ST-CFG-0051 | G12: 31.6992 | H12: 988-pack GENERATED
A13: 1001102 | B13: AKÜ,C-FLAT,DK,225AH,EAS PRIDE,İÇ PYS | C13: 1 | D13: ST-021-STD-04 | E13: IA-ST-021-STD-04 | F13: IA-ST-CFG-0024 | G13: 31.5384 | H13: 988-pack GENERATED
A14: 1002103 | B14: AKÜ,TRAKTÖRL,DK,115AH,EAS PRIDE,İÇ PYS | C14: 1 | D14: ST-045-STD-09 | E14: IA-ST-045-STD-09 | F14: IA-ST-CFG-0097 | G14: 33.063 | H14: 988-pack GENERATED
A15: 1002104 | B15: AKÜ,TRAKTÖR,DK,125AH,EAS PRIDE,İÇ PYS | C15: 1 | D15: ST-045-STD-09 | E15: IA-ST-045-STD-09 | F15: IA-ST-CFG-0097 | G15: 33.063 | H15: 988-pack GENERATED
A16: 1002216 | B16: AKÜ,B-FLAT,DK,180AH,İNCİ SUPRA,EEC MISIR | C16: 1 | D16: ST-030-STD-06 | E16: IA-ST-030-STD-06 | F16: IA-ST-CFG-0052 | G16: 32.3892 | H16: 988-pack GENERATED
A17: 1002422 | B17: AKÜ,B-FLAT,DK,170AH,HUGEL ACTION | C17: 1 | D17: ST-030-STD-06 | E17: IA-ST-030-STD-06 | F17: IA-ST-CFG-0052 | G17: 32.3892 | H17: 988-pack GENERATED
A18: 1002873 | B18: AKÜ,A-FLAT,DK,135AH,HUGEL ACTION | C18: 1 | D18: ST-030-STD-05 | E18: IA-ST-030-STD-05 | F18: IA-ST-CFG-0051 | G18: 31.6992 | H18: 988-pack GENERATED
... A39: 1004497 | B39: AKÜ,A-FLAT,DK,135AH,BLIZZARO TRENDLINE | C39: 1 | D39: ST-030-STD-05 | E39: IA-ST-030-STD-05 | F39: IA-ST-CFG-0051 | G39: 31.6992 | H39: 988-pack GENERATED
A40: 1004590 | B40: AKÜ,TRACTOR,DK,125AH,B00,SUPRA,AIOS OEM | C40: 1 | H40: NO MAPPING
A41: 1004591 | B41: AKÜ,TRACTORL,DK,105AH,B01,SUPRA,AIOS OEM | C41: 1 | H41: NO MAPPING
A42: 1004599 | B42: AKÜ,TRACTORL,DK,115AH,B00,İNCİSUPR,TEMSA | C42: 1 | H42: NO MAPPING
A43: 1004600 | B43: AKÜ,TRACTORL,DK,105AH,İNCİSUPRA,TEMSAOEM | C43: 1 | H43: NO MAPPING
A44: 1005175 | B44: AKÜ,B-FLAT,DK,180AH,İNCİ SUPRA SENT,EURO | C44: 1 | D44: ST-021-EUR-03 | E44: IA-ST-021-EUR-03 | F44: IA-ST-CFG-0029 | G44: 30.7682 | H44: 988-pack GENERATED
A45: 1005176 | B45: AKÜ,C-FLAT,DK,225AH,İNCİ SUPRA SENT,EURO | C45: 1 | D45: ST-018-EUR-03 | E45: IA-ST-018-EUR-03 | F45: IA-ST-CFG-0014 | G45: 30.9872 | H45: 988-pack GENERATED
A46: 1005491 | B46: AKÜ,TRACTORL,DK,105AH,CARGO,MAKO,OES | C46: 1 | H46: NO MAPPING
A47: 1005780 | B47: AKÜ,C-IGYA,DK,225AH,İNCİ SUPRA,TEMSA OEM | C47: 1 | H47: NO MAPPING
A48: 1005826 | B48: AKÜ,C-IGYA,DK,210AH,İNCİ SUPRASENTOR,BMC | C48: 1 | H48: NO MAPPING
A49: 1005827 | B49: AKÜ,C-IGYA,DK,225AH,İNCİ SUPRA,BMC,HORT | C49: 1 | H49: NO MAPPING
A50: 1005828 | B50: AKÜ,B-FLAT,DK,180AH,İNCİ SUPRASENTOR,BMC | C50: 1 | H50: NO MAPPING
A51: 1005829 | B51: AKÜ,B-IGYA,DK,180AH,SUPRA,BMCOTOBÜS,HORT | C51: 1 | H51: NO MAPPING
A52: 1005833 | B52: AKÜ,TRACTORL,DK,115AH,B01,SUPRA,ERKUNT | C52: 1 | H52: NO MAPPING
A53: 1005922 | B53: AKÜ,TRACTORL,DK,105AH,B01,SUPRA,ERKUNT | C53: 1 | H53: NO MAPPING
A54: 1006036 | B54: AKÜ,A-FLAT,DK,135AH,CARGO,MAKO,OES | C54: 1 | H54: NO MAPPING
A55: 1006037 | B55: AKÜ,B-FLAT,DK,150AH,CARGO,MAKO,OES | C55: 1 | H55: NO MAPPING
A56: 1006039 | B56: AKÜ,B-FLAT,DK,180AH,CARGO,MAKO,OES | C56: 1 | H56: NO MAPPING
A57: 1006040 | B57: AKÜ,C-FLAT,DK,200AH,CARGO,MAKO,OES | C57: 1 | D57: ST-018-EUR-05 | E57: IA-ST-018-EUR-05 | F57: IA-ST-CFG-0016 | G57: 30.7004 | H57: 988-pack GENERATED
A58: 1006041 | B58: AKÜ,C-FLAT,DK,225AH,CARGO,MAKO,OES | C58: 1 | D58: ST-018-EUR-05 | E58: IA-ST-018-EUR-05 | F58: IA-ST-CFG-0016 | G58: 30.7004 | H58: 988-pack GENERATED
A59: 1006054 | B59: AKÜ,C-IGYA,DK,240AH,İNCİ SUPRASENTOR,BMC | C59: 1 | H59: NO MAPPING
A60: 1006077 | B60: AKÜ,A-IGYASMF,DK,120AH,İNCİFORMULATAURUS | C60: 1 | D60: ST-030-STD-05 | E60: IA-ST-030-STD-05 | F60: IA-ST-CFG-0051 | G60: 31.6992 | H60: 988-pack GENERATED
A61: 1006081 | B61: AKÜ,A-IGYASMF,DK,135AH,İNCİFORMULATAURUS | C61: 1 | D61: ST-030-STD-05 | E61: IA-ST-030-STD-05 | F61: IA-ST-CFG-0051 | G61: 31.6992 | H61: 988-pack GENERATED
...

Sheet COMPONENT_MASTER
A1: ← HOME | B1: NAVIGATION | C1: SEARCH | D1: DOCUMENT CENTER | H1: REV.00
A2: COMPONENT MASTER
A3: Packaging component catalogue
A4: 112 · RECORDS | C4: 00 · REV | E4: READY · STATUS | G4: YES · LINKED
A6: ERP Component Code | B6: Description | C6: Component Type | D6: Material Family | E6: UOM | F6: Controlled Unit Weight (g) | G6: Supplier | H6: Evidence Status | I6: Configs Using Component
A7: 3503036 | B7: END OTO DOLUM SAF SU BIDONU 25L | C7: 14 | E7: ADT | F7: 1140 | H7: See evidence archive | I7: 1
A8: 3506099 | B8: END OTO DOLUM SAF SU BIDONU 20L | C8: 14 | E8: ADT | F8: 1140 | H8: See evidence archive | I8: 2
A9: 4000033 | B9: KARTON KÖŞEBENT,4cm*4cm*4*100cm,SEVPLT | C9: 14 | E9: ADT | F9: 210 | H9: See evidence archive | I9: 78
A10: 4000035 | B10: STRECH,23MC,50CM*300M | C10: 14 | E10: ADT | F10: 14.85 | H10: See evidence archive | I10: 3
A11: 4000037 | B11: PALET STANDART,1030*1110*152 | C11: 14 | E11: ADT | F11: 26000 | H11: See evidence archive | I11: 150
A12: 4000038 | B12: PALET EURO,800*1200*152 | C12: 14 | E12: ADT | F12: 26000 | H12: See evidence archive | I12: 88
A13: 4000130 | B13: KARTON SEPERATÖR,102*105,B DALGA | C13: 14 | E13: ADT | F13: 270 | H13: See evidence archive | I13: 154
A14: 4000300 | B14: STRECH,23MC,50CM*1500M,MAKİNA STRECH | C14: 14 | E14: ADT | F14: 18.32 | H14: See evidence archive | I14: 240
A15: 4000301 | B15: STRECH PED,80MC,140CM*170CM | C15: 14 | E15: ADT | F15: 1000 | H15: See evidence archive | I15: 221
A16: 4000350 | B16: PALET STANDART 100*90 CM | C16: 14 | E16: ADT | F16: 20000 | H16: See evidence archive | I16: 2
A17: 4000370 | B17: STRAFOR,1050*1000*40,TABAKA,STANDART | C17: 14 | E17: ADT | F17: 104 | H17: See evidence archive | I17: 10
A18: 4000440 | B18: D26,VAKUM PVC,ÜST KAPAK | C18: 14 | E18: ADT | F18: 64 | H18: See evidence archive | I18: 4
... A118: IND-LABELS | B118: Tüm Etiketler | C118: 14 | E118: ADT | F118: 5 | H118: See evidence archive | I118: 3

Sheet DOCUMENT_CENTER
A1: ← HOME | B1: NAVIGATION | C1: SEARCH | D1: DOCUMENT CENTER | H1: REV.00
A2: DOCUMENT CENTER
A3: Per-configuration document pack — Technical File, DoC, Label, Statement
A4: 247 · CONFIGURATIONS | C4: 988 · DOCUMENTS | E4: 988 · LINKED | G4: 0 · BLOCKING
A6: Packaging Set Code | B6: Configuration ID | C6: Variant Basis TR | D6: Variant Basis EN | E6: Source BOM ID | F6: Family | G6: Packaging Tare kg | H6: Product Count | I6: Technical File ID | J6: Open Technical File | K6: EU DoC ID | L6: Open EU DoC | M6: Label ID | N6: Open Label | O6: Statement ID | P6: Open Statement | Q6: Document Status | R6: Revision
A7: CNT-20-EUR-01 | B7: IA-CNT-20-EUR-01 | C7: Container loading | OSB (5501806): 11 adet | Separatör (4000130): 10 adet | D7: Container loading | OSB (5501806): 11 pcs | Separator (4000130): 10 pcs | E7: IA-CNT-20-EUR | F7: CONTAINER | G7: 83.06 | H7: 0 | I7: IA-PPWR-TF-CNT-20-EUR-01-R00 | J7: Open | K7: IA-PPWR-DOC-CNT-20-EUR-01-R00 | L7: Open | M7: IA-PPWR-LBL-CNT-20-EUR-01-R00 | N7: Open | O7: IA-PPWR-STM-CNT-20-EUR-01-R00 | P7: Open | Q7: GENERATED / LINKED | R7: Rev.00
A8: CNT-20-STD-01 | B8: IA-CNT-20-STD-01 | C8: Container loading | OSB (5501805): 10 adet | Separatör (4000130): 10 adet | D8: Container loading | OSB (5501805): 10 pcs | Separator (4000130): 10 pcs | E8: IA-CNT-20-STD | F8: CONTAINER | G8: 78.06 | H8: 0 | I8: IA-PPWR-TF-CNT-20-STD-01-R00 | J8: Open | K8: IA-PPWR-DOC-CNT-20-STD-01-R00 | L8: Open | M8: IA-PPWR-LBL-CNT-20-STD-01-R00 | N8: Open | O8: IA-PPWR-STM-CNT-20-STD-01-R00 | P8: Open | Q8: GENERATED / LINKED | R8: Rev.00
A9: CNT-40-IND-01 | B9: IA-CNT-40-IND-01 | C9: Container loading | Hava yastığı (5500759): 26 adet | Bağlama halatı (5500762): 12 m | D9: Container loading | Air dunnage (5500759): 26 pcs | Lashing rope (5500762): 12 m | E9: IA-CNT-40-IND | F9: CONTAINER | G9: 12.76 | H9: 0 | I9: IA-PPWR-TF-CNT-40-IND-01-R00 | J9: Open | K9: IA-PPWR-DOC-CNT-40-IND-01-R00 | L9: Open | M9: IA-PPWR-LBL-CNT-40-IND-01-R00 | N9: Open | O9: IA-PPWR-STM-CNT-40-IND-01-R00 | P9: Open | Q9: GENERATED / LINKED | R9: Rev.00
A10: CNT-DE-HAM-01 | B10: IA-CNT-DE-HAM-01 | C10: Container loading | Sabitleme Tahtası ( 206×9×9 ) (Hamburg): 2 adet | D10: Container loading | Sabitleme Tahtası ( 206×9×9 ) (Hamburg): 2 pcs | E10: IA-CNT-DE-HAMBURG | F10: CONTAINER | G10: 194 | H10: 0 | I10: IA-PPWR-TF-CNT-DE-HAM-01-R00 | J10: Open | K10: IA-PPWR-DOC-CNT-DE-HAM-01-R00 | L10: Open | M10: IA-PPWR-LBL-CNT-DE-HAM-01-R00 | N10: Open | O10: IA-PPWR-STM-CNT-DE-HAM-01-R00 | P10: Open | Q10: GENERATED / LINKED | R10: Rev.00
A11: IND-24V-01 | B11: IA-IND-24V-01 | C11: 24V | Palet (4001005): 1 adet | D11: 24V | Pallet (4001005): 1 pc | E11: IA-IND-24V | F11: INDUSTRIAL | G11: 27.388 | H11: 0 | I11: IA-PPWR-TF-IND-24V-01-R00 | J11: Open | K11: IA-PPWR-DOC-IND-24V-01-R00 | L11: Open | M11: IA-PPWR-LBL-IND-24V-01-R00 | N11: Open | O11: IA-PPWR-STM-IND-24V-01-R00 | P11: Open | Q11: GENERATED / LINKED | R11: Rev.00
A12: IND-48V-01 | B12: IA-IND-48V-01 | C12: 48V | Palet (4001005): 1 adet | D12: 48V | Pallet (4001005): 1 pc | E12: IA-IND-48V | F12: INDUSTRIAL | G12: 27.5767 | H12: 0 | I12: IA-PPWR-TF-IND-48V-01-R00 | J12: Open | K12: IA-PPWR-DOC-IND-48V-01-R00 | L12: Open | M12: IA-PPWR-LBL-IND-48V-01-R00 | N12: Open | O12: IA-PPWR-STM-IND-48V-01-R00 | P12: Open | Q12: GENERATED / LINKED | R12: Rev.00
A13: IND-80V-01 | B13: IA-IND-80V-01 | C13: 80V | Palet (4000973): 1 adet | D13: 80V | Pallet (4000973): 1 pc | E13: IA-IND-80V | F13: INDUSTRIAL | G13: 32.63147 | H13: 0 | I13: IA-PPWR-TF-IND-80V-01-R00 | J13: Open | K13: IA-PPWR-DOC-IND-80V-01-R00 | L13: Open | M13: IA-PPWR-LBL-IND-80V-01-R00 | N13: Open | O13: IA-PPWR-STM-IND-80V-01-R00 | P13: Open | Q13: GENERATED / LINKED | R13: Rev.00
A14: ST-012-EUR-01 | B14: IA-ST-012-EUR-01 | C14: C | Palet (4000038): 1 adet | Köşebent (4000590): 4 adet | D14: C | Pallet (4000038): 1 pc | Edge protector (4000590): 4 pcs | E14: IA-ST-CFG-0004 | F14: STARTER | G14: 29.326 | H14: 1 | I14: IA-PPWR-TF-ST-012-EUR-01-R00 | J14: Open | K14: IA-PPWR-DOC-ST-012-EUR-01-R00 | L14: Open | M14: IA-PPWR-LBL-ST-012-EUR-01-R00 | N14: Open | O14: IA-PPWR-STM-ST-012-EUR-01-R00 | P14: Open | Q14: GENERATED / LINKED | R14: Rev.00
A15: ST-012-EUR-02 | B15: IA-ST-012-EUR-02 | C15: L6 | Palet (4000038): 1 adet | Köşebent (4000590): 4 adet | D15: L6 | Pallet (4000038): 1 pc | Edge protector (4000590): 4 pcs | E15: IA-ST-CFG-0005 | F15: STARTER | G15: 27.526 | H15: 1 | I15: IA-PPWR-TF-ST-012-EUR-02-R00 | J15: Open | K15: IA-PPWR-DOC-ST-012-EUR-02-R00 | L15: Open | M15: IA-PPWR-LBL-ST-012-EUR-02-R00 | N15: Open | O15: IA-PPWR-STM-ST-012-EUR-02-R00 | P15: Open | Q15: GENERATED / LINKED | R15: Rev.00
A16: ST-012-EUR-03 | B16: IA-ST-012-EUR-03 | C16: C | Palet (4000038): 1 adet | Köşebent (4000590): 2 adet | D16: C | Pallet (4000038): 1 pc | Edge protector (4000590): 2 pcs | E16: IA-ST-CFG-0006 | F16: STARTER | G16: 29.0392 | H16: 2 | I16: IA-PPWR-TF-ST-012-EUR-03-R00 | J16: Open | K16: IA-PPWR-DOC-ST-012-EUR-03-R00 | L16: Open | M16: IA-PPWR-LBL-ST-012-EUR-03-R00 | N16: Open | O16: IA-PPWR-STM-ST-012-EUR-03-R00 | P16: Open | Q16: GENERATED / LINKED | R16: Rev.00
A17: ST-018-EUR-01 | B17: IA-ST-018-EUR-01 | C17: C | Palet (4000038): 1 adet | Köşebent (4001160): 4 adet | D17: C | Pallet (4000038): 1 pc | Edge protector (4001160): 4 pcs | E17: IA-ST-CFG-0012 | F17: STARTER | G17: 32.434 | H17: 1 | I17: IA-PPWR-TF-ST-018-EUR-01-R00 | J17: Open | K17: IA-PPWR-DOC-ST-018-EUR-01-R00 | L17: Open | M17: IA-PPWR-LBL-ST-018-EUR-01-R00 | N17: Open | O17: IA-PPWR-STM-ST-018-EUR-01-R00 | P17: Open | Q17: GENERATED / LINKED | R17: Rev.00
A18: ST-018-EUR-02 | B18: IA-ST-018-EUR-02 | C18: C | Palet (4000038): 1 adet | Köşebent (4000590): 4 adet | D18: C | Pallet (4000038): 1 pc | Edge protector (4000590): 4 pcs | E18: IA-ST-CFG-0013 | F18: STARTER | G18: 30.194 | H18: 4 | I18: IA-PPWR-TF-ST-018-EUR-02-R00 | J18: Open | K18: IA-PPWR-DOC-ST-018-EUR-02-R00 | L18: Open | M18: IA-PPWR-LBL-ST-018-EUR-02-R00 | N18: Open | O18: IA-PPWR-STM-ST-018-EUR-02-R00 | P18: Open | Q18: GENERATED / LINKED | R18: Rev.00
... A253: ST-120-STD-03 | B253: IA-ST-120-STD-03 | C253: NS40 | Palet (4000037): 1 adet | Shrink film (4001177): 0.597 kg | D253: NS40 | Pallet (4000037): 1 pc | Shrink film (4001177): 0.597 kg | E253: IA-ST-CFG-0286 | F253: STARTER | G253: 28.649 | H253: 4 | I253: IA-PPWR-TF-ST-120-STD-03-R00 | J253: Open | K253: IA-PPWR-DOC-ST-120-STD-03-R00 | L253: Open | M253: IA-PPWR-LBL-ST-120-STD-03-R00 | N253: Open | O253: IA-PPWR-STM-ST-120-STD-03-R00 | P253: Open | Q253: GENERATED / LINKED | R253: Rev.00

Sheet TECHNICAL_FILES
A1: ← HOME | B1: NAVIGATION | C1: SEARCH | D1: DOCUMENT CENTER | H1: REV.00
A2: TECHNICAL FILES
A3: PPWR technical file index — one per packaging configuration
A4: 247 · RECORDS | C4: 00 · REV | E4: READY · STATUS | G4: YES · LINKED
A6: Technical File Code | B6: Packaging Set Code | C6: Configuration ID | D6: Variant Basis | E6: Source BOM | F6: Product Count | G6: BOM Line Count | H6: Packaging Tare | I6: Article 5 Assessment Basis | J6: Drawing Status | K6: Photo Status | L6: Revision | M6: Open Technical File
A7: IA-PPWR-TF-CNT-20-EUR-01-R00 | B7: CNT-20-EUR-01 | C7: IA-CNT-20-EUR-01 | D7: Container loading | OSB (5501806): 11 adet | Separatör (4000130): 10 adet | E7: IA-CNT-20-EUR | F7: 0 | G7: 8 | H7: 83.06 | I7: REV00 CURRENT EVIDENCE BASIS — ARTICLE 5 ASSESSMENT BASIS | J7: PENDING - DRAWING | K7: PENDING - PHOTOGRAPHS | L7: Rev.00 | M7: Open
A8: IA-PPWR-TF-CNT-20-STD-01-R00 | B8: CNT-20-STD-01 | C8: IA-CNT-20-STD-01 | D8: Container loading | OSB (5501805): 10 adet | Separatör (4000130): 10 adet | E8: IA-CNT-20-STD | F8: 0 | G8: 8 | H8: 78.06 | I8: REV00 CURRENT EVIDENCE BASIS — ARTICLE 5 ASSESSMENT BASIS | J8: PENDING - DRAWING | K8: PENDING - PHOTOGRAPHS | L8: Rev.00 | M8: Open
A9: IA-PPWR-TF-CNT-40-IND-01-R00 | B9: CNT-40-IND-01 | C9: IA-CNT-40-IND-01 | D9: Container loading | Hava yastığı (5500759): 26 adet | Bağlama halatı (5500762): 12 m | E9: IA-CNT-40-IND | F9: 0 | G9: 5 | H9: 12.76 | I9: REV00 CURRENT EVIDENCE BASIS — ARTICLE 5 ASSESSMENT BASIS | J9: PENDING - DRAWING | K9: PENDING - PHOTOGRAPHS | L9: Rev.00 | M9: Open
A10: IA-PPWR-TF-CNT-DE-HAM-01-R00 | B10: CNT-DE-HAM-01 | C10: IA-CNT-DE-HAM-01 | D10: Container loading | Sabitleme Tahtası ( 206×9×9 ) (Hamburg): 2 adet | E10: IA-CNT-DE-HAMBURG | F10: 0 | G10: 3 | H10: 194 | I10: REV00 CURRENT EVIDENCE BASIS — ARTICLE 5 ASSESSMENT BASIS | J10: PENDING - DRAWING | K10: PENDING - PHOTOGRAPHS | L10: Rev.00 | M10: Open
A11: IA-PPWR-TF-IND-24V-01-R00 | B11: IND-24V-01 | C11: IA-IND-24V-01 | D11: 24V | Palet (4001005): 1 adet | E11: IA-IND-24V | F11: 0 | G11: 6 | H11: 27.388 | I11: REV00 CURRENT EVIDENCE BASIS — ARTICLE 5 ASSESSMENT BASIS | J11: PENDING - DRAWING | K11: PENDING - PHOTOGRAPHS | L11: Rev.00 | M11: Open
A12: IA-PPWR-TF-IND-48V-01-R00 | B12: IND-48V-01 | C12: IA-IND-48V-01 | D12: 48V | Palet (4001005): 1 adet | E12: IA-IND-48V | F12: 0 | G12: 6 | H12: 27.5767 | I12: REV00 CURRENT EVIDENCE BASIS — ARTICLE 5 ASSESSMENT BASIS | J12: PENDING - DRAWING | K12: PENDING - PHOTOGRAPHS | L12: Rev.00 | M12: Open
A13: IA-PPWR-TF-IND-80V-01-R00 | B13: IND-80V-01 | C13: IA-IND-80V-01 | D13: 80V | Palet (4000973): 1 adet | E13: IA-IND-80V | F13: 0 | G13: 6 | H13: 32.63147 | I13: REV00 CURRENT EVIDENCE BASIS — ARTICLE 5 ASSESSMENT BASIS | J13: PENDING - DRAWING | K13: PENDING - PHOTOGRAPHS | L13: Rev.00 | M13: Open
A14: IA-PPWR-TF-ST-012-EUR-01-R00 | B14: ST-012-EUR-01 | C14: IA-ST-012-EUR-01 | D14: C | Palet (4000038): 1 adet | Köşebent (4000590): 4 adet | E14: IA-ST-CFG-0004 | F14: 1 | G14: 7 | H14: 29.326 | I14: REV00 CURRENT EVIDENCE BASIS — ARTICLE 5 ASSESSMENT BASIS | J14: PENDING - DRAWING | K14: PENDING - PHOTOGRAPHS | L14: Rev.00 | M14: Open
A15: IA-PPWR-TF-ST-012-EUR-02-R00 | B15: ST-012-EUR-02 | C15: IA-ST-012-EUR-02 | D15: L6 | Palet (4000038): 1 adet | Köşebent (4000590): 4 adet | E15: IA-ST-CFG-0005 | F15: 1 | G15: 6 | H15: 27.526 | I15: REV00 CURRENT EVIDENCE BASIS — ARTICLE 5 ASSESSMENT BASIS | J15: PENDING - DRAWING | K15: PENDING - PHOTOGRAPHS | L15: Rev.00 | M15: Open
A16: IA-PPWR-TF-ST-012-EUR-03-R00 | B16: ST-012-EUR-03 | C16: IA-ST-012-EUR-03 | D16: C | Palet (4000038): 1 adet | Köşebent (4000590): 2 adet | E16: IA-ST-CFG-0006 | F16: 2 | G16: 7 | H16: 29.0392 | I16: REV00 CURRENT EVIDENCE BASIS — ARTICLE 5 ASSESSMENT BASIS | J16: PENDING - DRAWING | K16: PENDING - PHOTOGRAPHS | L16: Rev.00 | M16: Open
A17: IA-PPWR-TF-ST-018-EUR-01-R00 | B17: ST-018-EUR-01 | C17: IA-ST-018-EUR-01 | D17: C | Palet (4000038): 1 adet | Köşebent (4001160): 4 adet | E17: IA-ST-CFG-0012 | F17: 1 | G17: 9 | H17: 32.434 | I17: REV00 CURRENT EVIDENCE BASIS — ARTICLE 5 ASSESSMENT BASIS | J17: PENDING - DRAWING | K17: PENDING - PHOTOGRAPHS | L17: Rev.00 | M17: Open
A18: IA-PPWR-TF-ST-018-EUR-02-R00 | B18: ST-018-EUR-02 | C18: IA-ST-018-EUR-02 | D18: C | Palet (4000038): 1 adet | Köşebent (4000590): 4 adet | E18: IA-ST-CFG-0013 | F18: 4 | G18: 7 | H18: 30.194 | I18: REV00 CURRENT EVIDENCE BASIS — ARTICLE 5 ASSESSMENT BASIS | J18: PENDING - DRAWING | K18: PENDING - PHOTOGRAPHS | L18: Rev.00 | M18: Open
... A253: IA-PPWR-TF-ST-120-STD-03-R00 | B253: ST-120-STD-03 | C253: IA-ST-120-STD-03 | D253: NS40 | Palet (4000037): 1 adet | Shrink film (4001177): 0.597 kg | E253: IA-ST-CFG-0286 | F253: 4 | G253: 7 | H253: 28.649 | I253: REV00 CURRENT EVIDENCE BASIS — ARTICLE 5 ASSESSMENT BASIS | J253: PENDING - DRAWING | K253: PENDING - PHOTOGRAPHS | L253: Rev.00 | M253: Open

Sheet DECLARATIONS_OF_CONFORMITY
A1: ← HOME | B1: NAVIGATION | C1: SEARCH | D1: DOCUMENT CENTER | H1: REV.00
A2: DECLARATIONS OF CONFORMITY
A3: EU Declaration of Conformity index
A4: 247 · RECORDS | C4: 00 · REV | E4: READY · STATUS | G4: YES · LINKED
A6: DoC Number | B6: Packaging Set Code | C6: Configuration ID | D6: Packaging Description | E6: Variant Basis | F6: Source BOM ID | G6: Technical File ID | H6: Issue Date | I6: Revision | J6: Status | K6: Open DoC
A7: IA-PPWR-DOC-CNT-20-EUR-01-R00 | B7: CNT-20-EUR-01 | C7: IA-CNT-20-EUR-01 | D7: Container loading | OSB (5501806): 11 adet | Separatör (4000130): 10 adet | E7: Container loading | OSB (5501806): 11 adet | Separatör (4000130): 10 adet / Container loading | OSB (5501806): 11 pcs | Separator (4000130): 10 pcs | F7: IA-CNT-20-EUR | G7: IA-PPWR-TF-CNT-20-EUR-01-R00 | H7: 2026-08-08 | I7: Rev.00 | J7: ACTIVE — unsigned | K7: Open
A8: IA-PPWR-DOC-CNT-20-STD-01-R00 | B8: CNT-20-STD-01 | C8: IA-CNT-20-STD-01 | D8: Container loading | OSB (5501805): 10 adet | Separatör (4000130): 10 adet | E8: Container loading | OSB (5501805): 10 adet | Separatör (4000130): 10 adet / Container loading | OSB (5501805): 10 pcs | Separator (4000130): 10 pcs | F8: IA-CNT-20-STD | G8: IA-PPWR-TF-CNT-20-STD-01-R00 | H8: 2026-08-08 | I8: Rev.00 | J8: ACTIVE — unsigned | K8: Open
A9: IA-PPWR-DOC-CNT-40-IND-01-R00 | B9: CNT-40-IND-01 | C9: IA-CNT-40-IND-01 | D9: Container loading | Hava yastığı (5500759): 26 adet | Bağlama halatı (5500762): 12 m | E9: Container loading | Hava yastığı (5500759): 26 adet | Bağlama halatı (5500762): 12 m / Container loading | Air dunnage (5500759): 26 pcs | Lashing rope (5500762): 12 m | F9: IA-CNT-40-IND | G9: IA-PPWR-TF-CNT-40-IND-01-R00 | H9: 2026-08-08 | I9: Rev.00 | J9: ACTIVE — unsigned | K9: Open
A10: IA-PPWR-DOC-CNT-DE-HAM-01-R00 | B10: CNT-DE-HAM-01 | C10: IA-CNT-DE-HAM-01 | D10: Container loading | Sabitleme Tahtası ( 206×9×9 ) (Hamburg): 2 adet | E10: Container loading | Sabitleme Tahtası ( 206×9×9 ) (Hamburg): 2 adet / Container loading | Sabitleme Tahtası ( 206×9×9 ) (Hamburg): 2 pcs | F10: IA-CNT-DE-HAMBURG | G10: IA-PPWR-TF-CNT-DE-HAM-01-R00 | H10: 2026-08-08 | I10: Rev.00 | J10: ACTIVE — unsigned | K10: Open
A11: IA-PPWR-DOC-IND-24V-01-R00 | B11: IND-24V-01 | C11: IA-IND-24V-01 | D11: 24V | Palet (4001005): 1 adet | E11: 24V | Palet (4001005): 1 adet / 24V | Pallet (4001005): 1 pc | F11: IA-IND-24V | G11: IA-PPWR-TF-IND-24V-01-R00 | H11: 2026-08-08 | I11: Rev.00 | J11: ACTIVE — unsigned | K11: Open
A12: IA-PPWR-DOC-IND-48V-01-R00 | B12: IND-48V-01 | C12: IA-IND-48V-01 | D12: 48V | Palet (4001005): 1 adet | E12: 48V | Palet (4001005): 1 adet / 48V | Pallet (4001005): 1 pc | F12: IA-IND-48V | G12: IA-PPWR-TF-IND-48V-01-R00 | H12: 2026-08-08 | I12: Rev.00 | J12: ACTIVE — unsigned | K12: Open
A13: IA-PPWR-DOC-IND-80V-01-R00 | B13: IND-80V-01 | C13: IA-IND-80V-01 | D13: 80V | Palet (4000973): 1 adet | E13: 80V | Palet (4000973): 1 adet / 80V | Pallet (4000973): 1 pc | F13: IA-IND-80V | G13: IA-PPWR-TF-IND-80V-01-R00 | H13: 2026-08-08 | I13: Rev.00 | J13: ACTIVE — unsigned | K13: Open
A14: IA-PPWR-DOC-ST-012-EUR-01-R00 | B14: ST-012-EUR-01 | C14: IA-ST-012-EUR-01 | D14: C | Palet (4000038): 1 adet | Köşebent (4000590): 4 adet | E14: C | Palet (4000038): 1 adet | Köşebent (4000590): 4 adet / C | Pallet (4000038): 1 pc | Edge protector (4000590): 4 pcs | F14: IA-ST-CFG-0004 | G14: IA-PPWR-TF-ST-012-EUR-01-R00 | H14: 2026-08-08 | I14: Rev.00 | J14: ACTIVE — unsigned | K14: Open
A15: IA-PPWR-DOC-ST-012-EUR-02-R00 | B15: ST-012-EUR-02 | C15: IA-ST-012-EUR-02 | D15: L6 | Palet (4000038): 1 adet | Köşebent (4000590): 4 adet | E15: L6 | Palet (4000038): 1 adet | Köşebent (4000590): 4 adet / L6 | Pallet (4000038): 1 pc | Edge protector (4000590): 4 pcs | F15: IA-ST-CFG-0005 | G15: IA-PPWR-TF-ST-012-EUR-02-R00 | H15: 2026-08-08 | I15: Rev.00 | J15: ACTIVE — unsigned | K15: Open
A16: IA-PPWR-DOC-ST-012-EUR-03-R00 | B16: ST-012-EUR-03 | C16: IA-ST-012-EUR-03 | D16: C | Palet (4000038): 1 adet | Köşebent (4000590): 2 adet | E16: C | Palet (4000038): 1 adet | Köşebent (4000590): 2 adet / C | Pallet (4000038): 1 pc | Edge protector (4000590): 2 pcs | F16: IA-ST-CFG-0006 | G16: IA-PPWR-TF-ST-012-EUR-03-R00 | H16: 2026-08-08 | I16: Rev.00 | J16: ACTIVE — unsigned | K16: Open
A17: IA-PPWR-DOC-ST-018-EUR-01-R00 | B17: ST-018-EUR-01 | C17: IA-ST-018-EUR-01 | D17: C | Palet (4000038): 1 adet | Köşebent (4001160): 4 adet | E17: C | Palet (4000038): 1 adet | Köşebent (4001160): 4 adet / C | Pallet (4000038): 1 pc | Edge protector (4001160): 4 pcs | F17: IA-ST-CFG-0012 | G17: IA-PPWR-TF-ST-018-EUR-01-R00 | H17: 2026-08-08 | I17: Rev.00 | J17: ACTIVE — unsigned | K17: Open
... A253: IA-PPWR-DOC-ST-120-STD-03-R00 | B253: ST-120-STD-03 | C253: IA-ST-120-STD-03 | D253: NS40 | Palet (4000037): 1 adet | Shrink film (4001177): 0.597 kg | E253: NS40 | Palet (4000037): 1 adet | Shrink film (4001177): 0.597 kg / NS40 | Pallet (4000037): 1 pc | Shrink film (4001177): 0.597 kg | F253: IA-ST-CFG-0286 | G253: IA-PPWR-TF-ST-120-STD-03-R00 | H253: 2026-08-08 | I253: Rev.00 | J253: ACTIVE — unsigned | K253: Open

Sheet LABELS
A1: ← HOME | B1: NAVIGATION | C1: SEARCH | D1: DOCUMENT CENTER | H1: REV.00
A2: LABELS
A3: Packaging identification label index
A4: 247 · RECORDS | C4: 00 · REV | E4: READY · STATUS | G4: YES · LINKED
A6: Label ID | B6: Packaging Set Code | C6: Configuration ID | D6: Variant Basis | E6: Material Families | F6: TF ID | G6: DoC ID | H6: Revision | I6: Open Label
A7: IA-PPWR-LBL-CNT-20-EUR-01-R00 | B7: CNT-20-EUR-01 | C7: IA-CNT-20-EUR-01 | D7: Container loading | OSB (5501806): 11 adet | Separatör (4000130): 10 adet | E7: See Technical File material-family summary | F7: IA-PPWR-TF-CNT-20-EUR-01-R00 | G7: IA-PPWR-DOC-CNT-20-EUR-01-R00 | H7: Rev.00 | I7: Open
A8: IA-PPWR-LBL-CNT-20-STD-01-R00 | B8: CNT-20-STD-01 | C8: IA-CNT-20-STD-01 | D8: Container loading | OSB (5501805): 10 adet | Separatör (4000130): 10 adet | E8: See Technical File material-family summary | F8: IA-PPWR-TF-CNT-20-STD-01-R00 | G8: IA-PPWR-DOC-CNT-20-STD-01-R00 | H8: Rev.00 | I8: Open
A9: IA-PPWR-LBL-CNT-40-IND-01-R00 | B9: CNT-40-IND-01 | C9: IA-CNT-40-IND-01 | D9: Container loading | Hava yastığı (5500759): 26 adet | Bağlama halatı (5500762): 12 m | E9: See Technical File material-family summary | F9: IA-PPWR-TF-CNT-40-IND-01-R00 | G9: IA-PPWR-DOC-CNT-40-IND-01-R00 | H9: Rev.00 | I9: Open
A10: IA-PPWR-LBL-CNT-DE-HAM-01-R00 | B10: CNT-DE-HAM-01 | C10: IA-CNT-DE-HAM-01 | D10: Container loading | Sabitleme Tahtası ( 206×9×9 ) (Hamburg): 2 adet | E10: See Technical File material-family summary | F10: IA-PPWR-TF-CNT-DE-HAM-01-R00 | G10: IA-PPWR-DOC-CNT-DE-HAM-01-R00 | H10: Rev.00 | I10: Open
A11: IA-PPWR-LBL-IND-24V-01-R00 | B11: IND-24V-01 | C11: IA-IND-24V-01 | D11: 24V | Palet (4001005): 1 adet | E11: See Technical File material-family summary | F11: IA-PPWR-TF-IND-24V-01-R00 | G11: IA-PPWR-DOC-IND-24V-01-R00 | H11: Rev.00 | I11: Open
A12: IA-PPWR-LBL-IND-48V-01-R00 | B12: IND-48V-01 | C12: IA-IND-48V-01 | D12: 48V | Palet (4001005): 1 adet | E12: See Technical File material-family summary | F12: IA-PPWR-TF-IND-48V-01-R00 | G12: IA-PPWR-DOC-IND-48V-01-R00 | H12: Rev.00 | I12: Open
A13: IA-PPWR-LBL-IND-80V-01-R00 | B13: IND-80V-01 | C13: IA-IND-80V-01 | D13: 80V | Palet (4000973): 1 adet | E13: See Technical File material-family summary | F13: IA-PPWR-TF-IND-80V-01-R00 | G13: IA-PPWR-DOC-IND-80V-01-R00 | H13: Rev.00 | I13: Open
A14: IA-PPWR-LBL-ST-012-EUR-01-R00 | B14: ST-012-EUR-01 | C14: IA-ST-012-EUR-01 | D14: C | Palet (4000038): 1 adet | Köşebent (4000590): 4 adet | E14: See Technical File material-family summary | F14: IA-PPWR-TF-ST-012-EUR-01-R00 | G14: IA-PPWR-DOC-ST-012-EUR-01-R00 | H14: Rev.00 | I14: Open
A15: IA-PPWR-LBL-ST-012-EUR-02-R00 | B15: ST-012-EUR-02 | C15: IA-ST-012-EUR-02 | D15: L6 | Palet (4000038): 1 adet | Köşebent (4000590): 4 adet | E15: See Technical File material-family summary | F15: IA-PPWR-TF-ST-012-EUR-02-R00 | G15: IA-PPWR-DOC-ST-012-EUR-02-R00 | H15: Rev.00 | I15: Open
A16: IA-PPWR-LBL-ST-012-EUR-03-R00 | B16: ST-012-EUR-03 | C16: IA-ST-012-EUR-03 | D16: C | Palet (4000038): 1 adet | Köşebent (4000590): 2 adet | E16: See Technical File material-family summary | F16: IA-PPWR-TF-ST-012-EUR-03-R00 | G16: IA-PPWR-DOC-ST-012-EUR-03-R00 | H16: Rev.00 | I16: Open
A17: IA-PPWR-LBL-ST-018-EUR-01-R00 | B17: ST-018-EUR-01 | C17: IA-ST-018-EUR-01 | D17: C | Palet (4000038): 1 adet | Köşebent (4001160): 4 adet | E17: See Technical File material-family summary | F17: IA-PPWR-TF-ST-018-EUR-01-R00 | G17: IA-PPWR-DOC-ST-018-EUR-01-R00 | H17: Rev.00 | I17: Open
... A253: IA-PPWR-LBL-ST-120-STD-03-R00 | B253: ST-120-STD-03 | C253: IA-ST-120-STD-03 | D253: NS40 | Palet (4000037): 1 adet | Shrink film (4001177): 0.597 kg | E253: See Technical File material-family summary | F253: IA-PPWR-TF-ST-120-STD-03-R00 | G253: IA-PPWR-DOC-ST-120-STD-03-R00 | H253: Rev.00 | I253: Open

Sheet SHIPMENT_STATEMENTS
A1: ← HOME | B1: NAVIGATION | C1: SEARCH | D1: DOCUMENT CENTER | H1: REV.00
A2: SHIPMENT STATEMENTS
A3: Shipment statement index — one per packaging configuration
A4: 247 · RECORDS | C4: 00 · REV | E4: READY · STATUS | G4: YES · LINKED
A6: Statement ID | B6: Packaging Set Code | C6: Configuration ID | D6: Source BOM | E6: Variant Basis | F6: Packaging Tare | G6: BOM Line Count | H6: Revision | I6: Open Statement
A7: IA-PPWR-STM-CNT-20-EUR-01-R00 | B7: CNT-20-EUR-01 | C7: IA-CNT-20-EUR-01 | D7: IA-CNT-20-EUR | E7: Container loading | OSB (5501806): 11 adet | Separatör (4000130): 10 adet | F7: 83.06 | G7: 8 | H7: Rev.00 | I7: Open
A8: IA-PPWR-STM-CNT-20-STD-01-R00 | B8: CNT-20-STD-01 | C8: IA-CNT-20-STD-01 | D8: IA-CNT-20-STD | E8: Container loading | OSB (5501805): 10 adet | Separatör (4000130): 10 adet | F8: 78.06 | G8: 8 | H8: Rev.00 | I8: Open
A9: IA-PPWR-STM-CNT-40-IND-01-R00 | B9: CNT-40-IND-01 | C9: IA-CNT-40-IND-01 | D9: IA-CNT-40-IND | E9: Container loading | Hava yastığı (5500759): 26 adet | Bağlama halatı (5500762): 12 m | F9: 12.76 | G9: 5 | H9: Rev.00 | I9: Open
A10: IA-PPWR-STM-CNT-DE-HAM-01-R00 | B10: CNT-DE-HAM-01 | C10: IA-CNT-DE-HAM-01 | D10: IA-CNT-DE-HAMBURG | E10: Container loading | Sabitleme Tahtası ( 206×9×9 ) (Hamburg): 2 adet | F10: 194 | G10: 3 | H10: Rev.00 | I10: Open
A11: IA-PPWR-STM-IND-24V-01-R00 | B11: IND-24V-01 | C11: IA-IND-24V-01 | D11: IA-IND-24V | E11: 24V | Palet (4001005): 1 adet | F11: 27.388 | G11: 6 | H11: Rev.00 | I11: Open
A12: IA-PPWR-STM-IND-48V-01-R00 | B12: IND-48V-01 | C12: IA-IND-48V-01 | D12: IA-IND-48V | E12: 48V | Palet (4001005): 1 adet | F12: 27.5767 | G12: 6 | H12: Rev.00 | I12: Open
A13: IA-PPWR-STM-IND-80V-01-R00 | B13: IND-80V-01 | C13: IA-IND-80V-01 | D13: IA-IND-80V | E13: 80V | Palet (4000973): 1 adet | F13: 32.63147 | G13: 6 | H13: Rev.00 | I13: Open
A14: IA-PPWR-STM-ST-012-EUR-01-R00 | B14: ST-012-EUR-01 | C14: IA-ST-012-EUR-01 | D14: IA-ST-CFG-0004 | E14: C | Palet (4000038): 1 adet | Köşebent (4000590): 4 adet | F14: 29.326 | G14: 7 | H14: Rev.00 | I14: Open
A15: IA-PPWR-STM-ST-012-EUR-02-R00 | B15: ST-012-EUR-02 | C15: IA-ST-012-EUR-02 | D15: IA-ST-CFG-0005 | E15: L6 | Palet (4000038): 1 adet | Köşebent (4000590): 4 adet | F15: 27.526 | G15: 6 | H15: Rev.00 | I15: Open
A16: IA-PPWR-STM-ST-012-EUR-03-R00 | B16: ST-012-EUR-03 | C16: IA-ST-012-EUR-03 | D16: IA-ST-CFG-0006 | E16: C | Palet (4000038): 1 adet | Köşebent (4000590): 2 adet | F16: 29.0392 | G16: 7 | H16: Rev.00 | I16: Open
A17: IA-PPWR-STM-ST-018-EUR-01-R00 | B17: ST-018-EUR-01 | C17: IA-ST-018-EUR-01 | D17: IA-ST-CFG-0012 | E17: C | Palet (4000038): 1 adet | Köşebent (4001160): 4 adet | F17: 32.434 | G17: 9 | H17: Rev.00 | I17: Open
A18: IA-PPWR-STM-ST-018-EUR-02-R00 | B18: ST-018-EUR-02 | C18: IA-ST-018-EUR-02 | D18: IA-ST-CFG-0013 | E18: C | Palet (4000038): 1 adet | Köşebent (4000590): 4 adet | F18: 30.194 | G18: 7 | H18: Rev.00 | I18: Open
... A253: IA-PPWR-STM-ST-120-STD-03-R00 | B253: ST-120-STD-03 | C253: IA-ST-120-STD-03 | D253: IA-ST-CFG-0286 | E253: NS40 | Palet (4000037): 1 adet | Shrink film (4001177): 0.597 kg | F253: 28.649 | G253: 7 | H253: Rev.00 | I253: Open

Sheet SHIPMENTS
A1: ← HOME | B1: NAVIGATION | C1: SEARCH | D1: DOCUMENT CENTER | H1: REV.00
A2: SHIPMENTS
A3: Transactional shipment register
A4: EMPTY · STATUS | C4: 00 · REV | E4: 0 · RECORDS | G4: BASELINE · PHASE
A6: CURRENT STATUS
A7: No transactional shipment records are loaded in Rev.00 baseline.
A8: Shipment tracking will be activated for Rev.01 and the operational phase.
A10: QUICK LINKS
A11: → Open Shipment Database
A12: → Open Shipment Statements

Sheet DOC_ENGINE_MAP
A1: ← HOME | B1: NAVIGATION | C1: SEARCH | D1: DOCUMENT CENTER | F1: REV.00
A2: DOCUMENT ENGINE MAP
A3: Read-only mapping • Python remains document authority
A4: 9 · FIELDS | C4: READ-ONLY · MODE | E4: PYTHON · AUTHORITY
A6: Document Type | B6: Logical Field | C6: PIMS Source | D6: DocumentContext Field | E6: Runtime Token / Mapping | F6: Builder Module
A7: Technical File | B7: Packaging Set Code | C7: PACKAGING_CONFIGURATION.CONFIG_GROUP_CODE | D7: document_ids.packaging_set_code | E7: {{CONFIG_SET_CODE}} | F7: phase_g.merge_engine
A8: Technical File | B8: Configuration ID | C8: NOTES FINAL_CONFIGURATION_ID | D8: document_ids.final_configuration_id | E8: {{CONFIG_ID}} | F8: DocumentContextFactory
A9: Technical File | B9: Variant Basis TR/EN | C9: DESCRIPTION codec | D9: configuration.variant_basis_* | E9: {{VARIANT_BASIS_TR/EN}} | F9: VariantDescriptionCodec
A10: Technical File | B10: Exact BOM | C10: PACKAGING_CONFIGURATION_LINE | D10: configuration.lines | E10: {{BOM_TABLE}} | F10: merge_engine._fill_bom_table
A11: Technical File | B11: Tare | C11: WeightService | D11: total_tare_g | E11: {{TOTAL_TARE_KG}} | F11: WeightService
A12: EU DoC | B12: Declaration ID | C12: DECLARATION_OF_CONFORMITY.DOC_NUMBER | D12: document_ids.doc_id | E12: {{DOC_ID}} | F12: IdService
A13: Label | B13: Label ID | C13: DOCUMENT_LIBRARY DOCUMENT_CODE | D13: document_ids.label_id | E13: {{LABEL_ID}} | F13: IdService
A14: Statement | B14: Statement ID | C14: STATEMENT.STATEMENT_CODE | D14: document_ids.statement_id | E14: {{STM_ID}} | F14: IdService
A15: All | B15: FILE_URI | C15: DOCUMENT_LIBRARY | D15: n/a | E15: relative Phase I path | F15: phase_j.registry_sync

Sheet 00_README
A1: İnci Akü PPWR PIMS — Workbook Platform (Rev00)
A3: TR | EN
A4: Amaç / Purpose
A5: Bu çalışma kitabı, İnci Akü PPWR Ambalaj Bilgi Yönetim Sistemi’nin (PIMS) Wave-1 operasyonel ilişkisel veritabanıdır.
A6: This workbook is the Wave-1 operational relational database for the İnci Akü PPWR Packaging Information Management System (PIMS).
A8: Kaynak Gerçeği / Source of Truth
A9: Şema otoritesi: FINAL_DATABASE.md Schema 1.0.0 (FROZEN). Her ilişkisel tablo = bir sayfa. UI sayfaları (00–04) kaynak değildir.
A10: Schema authority: FINAL_DATABASE.md Schema 1.0.0 (FROZEN). One relational table = one sheet. UI sheets (00–04) are never source of truth.
A12: Sayfa Kategorileri / Sheet Categories
A13: 00–04: Arayüz / rehber. LKP_*: kontrollü lookup. SYSTEM: meta. Diğerleri: master / yapılandırma / sevkiyat / belge metadata.
A14: 00–04: UI / guides. LKP_*: controlled lookups. SYSTEM: metadata. Others: masters / configs / shipments / document metadata.
A16: Golden Variant
... A50: CIF ve CIP ayrı Incoterms 2020 kodlarıdır; ikisi de LKP_INCOTERM’de aktiftir. Alias değildir.

Sheet 01_DASHBOARD
A1: İnci Akü PPWR Packaging Information Management System — Rev.00
A2: Production Master Data: LOADED | Golden Variant Register: 247 / 247 | Document Pack: 988 / 988 GENERATED | Document Registry: 988 / 988 LINKED | Blocking QA Errors: 0
A4: KPI | B4: Count | C4: Status | D4: Notes
A5: Components | B5: =COUNTA(COMPONENT!A2:A5000) -> 112 | C5: LOADED | D5: Phase J — application layer + document registry sync
A6: Products | B6: =COUNTA(PRODUCT!A2:A5000) -> 2046 | C6: LOADED | D6: Phase J — application layer + document registry sync
A7: Final Packaging Configurations | B7: =COUNTA(PACKAGING_CONFIGURATION!A2:A5000) -> 247 | C7: LOADED | D7: Phase J — application layer + document registry sync
A8: Packaging BOM lines | B8: =COUNTA(PACKAGING_CONFIGURATION_LINE!A2:A5000) -> 1690 | C8: LOADED | D8: Phase J — application layer + document registry sync
A9: Transport Configurations | B9: =COUNTA(TRANSPORT_CONFIGURATION!A2:A5000) -> 247 | C9: LOADED | D9: Phase J — application layer + document registry sync
A10: Commercial Scenarios | B10: =COUNTA(COMMERCIAL_SCENARIO!A2:A5000) -> 1917 | C10: LOADED | D10: Phase J — application layer + document registry sync
A11: Shipments | B11: =COUNTA(SHIPMENT!A2:A5000) -> 0 | C11: LOADED | D11: Phase J — application layer + document registry sync
A12: Technical Files | B12: =COUNTA(TECHNICAL_FILE!A2:A5000) -> 247 | C12: LOADED | D12: Phase J — application layer + document registry sync
A13: DoCs | B13: =COUNTA(DECLARATION_OF_CONFORMITY!A2:A5000) -> 247 | C13: LOADED | D13: Phase J — application layer + document registry sync
A14: Statements | B14: =COUNTA(STATEMENT!A2:A5000) -> 247 | C14: LOADED | D14: Phase J — application layer + document registry sync
A15: Evidence / Document Library | B15: =COUNTA(DOCUMENT_LIBRARY!A2:A5000) -> 988 | C15: LOADED | D15: Phase J — application layer + document registry sync
A16: Validation errors (platform) | B16: 0 | C16: SEE 02_RELEASE_CONTROL | D16: Platform shell — Phase F loads production
A18: Category breakdown (future)
A19: Starter | B19: 240 | C19: LOADED
A20: Industrial | B20: 3 | C20: LOADED
A21: Container | B21: 4 | C21: LOADED
A22: Returnable / Pool (schema hooks only) | B22: 0 | C22: HOOKS ONLY
A24: Lookup seed count (controlled vocabulary only)
A25: =COUNTA(LKP_STATUS!A2:A5000) -> 8 | B25: LKP_STATUS sample (others on LKP_* sheets)

Sheet 02_RELEASE_CONTROL
A1: 02_RELEASE_CONTROL — Platform readiness (not packaging conformity)
A2: Statuses refer to SYSTEM / WORKBOOK readiness. Production conformity is NOT assessed in Phase E.
A4: Control Area | B4: Rule | C4: Error Count | D4: Warning Count | E4: Status | F4: Blocking? | G4: Responsible Role | H4: Notes
A5: Schema | B5: FINAL_DATABASE.md 1.0.0 frozen; 43 table sheets present | C5: 0 | D5: 0 | E5: READY | F5: Yes | G5: Architecture | H5: Workbook schema: READY
A6: Master data | B6: Production COMPONENT / PRODUCT / CONFIG not loaded | C6: 0 | D6: 0 | E6: LOADED | F6: Yes | G6: Packaging Engineering | H6: Production master data: LOADED
A7: BOM | B7: PACKAGING_CONFIGURATION_LINE empty until Phase F | C7: 0 | D7: 0 | E7: LOADED | F7: Yes | G7: Packaging Engineering | H7: Final configurations / exact BOM: LOADED
A8: Product mapping | B8: COMMERCIAL_SCENARIO links product→transport→packaging | C8: 0 | D8: 0 | E8: LOADED | F8: Yes | G8: Sales / Engineering | H8: Product mapping: LOADED
A9: Evidence | B9: DOCUMENT_LIBRARY / LINK architecture present | C9: 0 | D9: 0 | E9: PLATFORM READY | F9: No | G9: Compliance | H9: No production evidence records
A10: Drawing / photo | B10: Document types DRAWING/PHOTO/ARTWORK seeded | C10: 0 | D10: 0 | E10: PLATFORM READY | F10: No | G10: Engineering | H10: Files not imported in Phase E
A11: Document generation | B11: Word/PDF builders exist as stubs only | C11: 0 | D11: 0 | E11: NOT RUN – PHASE G | F11: Yes | G11: IT / Compliance | H11: Document generation: NOT RUN – PHASE G
A12: Lookup vocabulary | B12: LKP_* seeded; CIP and CIF both present as distinct Incoterms | C12: 0 | D12: 0 | E12: READY | F12: Yes | G12: MDM | H12: Controlled seed only
A13: PK integrity framework | B13: PK highlight + blank/duplicate checks via Python QA / future CF | C13: 0 | D13: 0 | E13: FRAMEWORK READY | F13: Yes | G13: IT | H13: Empty masters intentionally blank
A14: FK integrity framework | B14: Lookup FK dropdowns; high-volume FK via Python QA | C14: 0 | D14: 0 | E14: FRAMEWORK READY | F14: Yes | G14: IT | H14: Relational FK defined by schema
A15: Weight derivation | B15: Python WeightService authoritative; ZZ_QA_WEIGHT_FIXTURE visibility | C15: 0 | D15: 0 | E15: PASSED | F15: No | G15: Engineering | H15: Weight validation: PASSED (247/247 gate)
A16: Article 5 | B16: Assessment fields available on TF; no auto ≤100 mg/kg | C16: 0 | D16: 0 | E16: NOT ASSESSED | F16: No | G16: Compliance | H16: No production assessment records

Sheet 03_DATA_DICTIONARY
A1: 03_DATA_DICTIONARY — Generated from Schema 1.0.0 metadata
A2: Generated from Python TableDefinition registry — do not maintain as parallel SoT.
A4: Table | B4: Column | C4: Data Type | D4: Required | E4: PK | F4: FK | G4: FK Target | H4: Business Meaning | I4: Data Owner | J4: Update Frequency | K4: Validation Rule | L4: System / User Managed
A5: SYS_WORKBOOK_INFO | B5: INFO_KEY | C5: TEXT | D5: Y | E5: Y | F5: N | H5: Schema version and workbook metadata | I5: IT / Solution Architecture | J5: On schema release only | K5: PK unique; not blank when row used | L5: USER
A6: SYS_WORKBOOK_INFO | B6: INFO_VALUE | C6: TEXT | D6: Y | E6: N | F6: N | H6: Schema version and workbook metadata | I6: IT / Solution Architecture | J6: On schema release only | K6: Text | L6: USER
A7: SYS_WORKBOOK_INFO | B7: UPDATED_AT | C7: DATETIME | D7: Y | E7: N | F7: N | H7: Schema version and workbook metadata | I7: IT / Solution Architecture | J7: On schema release only | K7: Text | L7: SYSTEM
A8: SYS_PARAMETER | B8: PARAMETER_ID | C8: INT | D8: Y | E8: Y | F8: N | H8: System behavior parameters | I8: Compliance + Architecture | J8: Rare | K8: PK unique; not blank when row used | L8: USER
A9: SYS_PARAMETER | B9: PARAMETER_CODE | C9: TEXT | D9: Y | E9: N | F9: N | H9: System behavior parameters | I9: Compliance + Architecture | J9: Rare | K9: Text | L9: USER
A10: SYS_PARAMETER | B10: PARAMETER_VALUE | C10: TEXT | D10: Y | E10: N | F10: N | H10: System behavior parameters | I10: Compliance + Architecture | J10: Rare | K10: Text | L10: USER
A11: SYS_PARAMETER | B11: DESCRIPTION | C11: TEXT | D11: N | E11: N | F11: N | H11: System behavior parameters | I11: Compliance + Architecture | J11: Rare | K11: Text | L11: USER
A12: LKP_STATUS | B12: STATUS_ID | C12: INT | D12: Y | E12: Y | F12: N | H12: Lifecycle/approval statuses by domain | I12: Architecture | J12: Rare | K12: PK unique; not blank when row used | L12: USER
A13: LKP_STATUS | B13: STATUS_CODE | C13: TEXT | D13: Y | E13: N | F13: N | H13: Lifecycle/approval statuses by domain | I13: Architecture | J13: Rare | K13: Text | L13: USER
A14: LKP_STATUS | B14: STATUS_NAME | C14: TEXT | D14: Y | E14: N | F14: N | H14: Lifecycle/approval statuses by domain | I14: Architecture | J14: Rare | K14: Text | L14: USER
A15: LKP_STATUS | B15: STATUS_DOMAIN | C15: TEXT | D15: Y | E15: N | F15: N | H15: Lifecycle/approval statuses by domain | I15: Architecture | J15: Rare | K15: Text | L15: USER
A16: LKP_STATUS | B16: IS_EDITABLE | C16: BOOL | D16: Y | E16: N | F16: N | H16: Lifecycle/approval statuses by domain | I16: Architecture | J16: Rare | K16: TRUE/FALSE | L16: USER
... A31: LKP_COMPONENT_TYPE | B31: COMPONENT_TYPE_NAME | C31: TEXT | D31: Y | E31: N | F31: N | H31: Component type vocabulary incl. container materials | I31: MDM + Compliance | J31: Rare | K31: Text | L31: USER
A32: LKP_COMPONENT_TYPE | B32: DEFAULT_PACKAGING_LEVEL_ID | C32: INT | D32: N | E32: N | F32: Y | G32: LKP_PACKAGING_LEVEL | H32: Component type vocabulary incl. container materials | I32: MDM + Compliance | J32: Rare | K32: Lookup list → LKP_PACKAGING_LEVEL | L32: USER
A33: LKP_MATERIAL_FAMILY | B33: MATERIAL_FAMILY_ID | C33: INT | D33: Y | E33: Y | F33: N | H33: Material families | I33: MDM + Compliance | J33: Rare | K33: PK unique; not blank when row used | L33: USER
A34: LKP_MATERIAL_FAMILY | B34: MATERIAL_FAMILY_CODE | C34: TEXT | D34: Y | E34: N | F34: N | H34: Material families | I34: MDM + Compliance | J34: Rare | K34: Text | L34: USER
A35: LKP_MATERIAL_FAMILY | B35: MATERIAL_FAMILY_NAME | C35: TEXT | D35: Y | E35: N | F35: N | H35: Material families | I35: MDM + Compliance | J35: Rare | K35: Text | L35: USER
A36: LKP_PPWR_MATERIAL_CATEGORY | B36: PPWR_MATERIAL_CATEGORY_ID | C36: INT | D36: Y | E36: Y | F36: N | H36: PPWR material categories | I36: MDM + Compliance | J36: Rare | K36: PK unique; not blank when row used | L36: USER
A37: LKP_PPWR_MATERIAL_CATEGORY | B37: PPWR_MATERIAL_CATEGORY_CODE | C37: TEXT | D37: Y | E37: N | F37: N | H37: PPWR material categories | I37: MDM + Compliance | J37: Rare | K37: Text | L37: USER
A38: LKP_PPWR_MATERIAL_CATEGORY | B38: PPWR_MATERIAL_CATEGORY_NAME | C38: TEXT | D38: Y | E38: N | F38: N | H38: PPWR material categories | I38: MDM + Compliance | J38: Rare | K38: Text | L38: USER
A39: LKP_MATERIAL | B39: MATERIAL_ID | C39: INT | D39: Y | E39: Y | F39: N | H39: Controlled material vocabulary | I39: MDM + Compliance | J39: Rare | K39: PK unique; not blank when row used | L39: USER
A40: LKP_MATERIAL | B40: MATERIAL_CODE | C40: TEXT | D40: Y | E40: N | F40: N | H40: Controlled material vocabulary | I40: MDM + Compliance | J40: Rare | K40: Text | L40: USER
A41: LKP_MATERIAL | B41: MATERIAL_NAME | C41: TEXT | D41: Y | E41: N | F41: N | H41: Controlled material vocabulary | I41: MDM + Compliance | J41: Rare | K41: Text | L41: USER
A42: LKP_MATERIAL | B42: MATERIAL_FAMILY_ID | C42: INT | D42: Y | E42: N | F42: Y | G42: LKP_MATERIAL_FAMILY | H42: Controlled material vocabulary | I42: MDM + Compliance | J42: Rare | K42: Lookup list → LKP_MATERIAL_FAMILY | L42: USER
A43: LKP_MATERIAL | B43: PPWR_MATERIAL_CATEGORY_ID | C43: INT | D43: N | E43: N | F43: Y | G43: LKP_PPWR_MATERIAL_CATEGORY | H43: Controlled material vocabulary | I43: MDM + Compliance | J43: Rare | K43: Lookup list → LKP_PPWR_MATERIAL_CATEGORY | L43: USER
A44: LKP_MATERIAL | B44: IS_COMPOSITE | C44: BOOL | D44: Y | E44: N | F44: N | H44: Controlled material vocabulary | I44: MDM + Compliance | J44: Rare | K44: TRUE/FALSE | L44: USER
A45: LKP_MATERIAL | B45: NOTES | C45: TEXT | D45: N | E45: N | F45: N | H45: Controlled material vocabulary | I45: MDM + Compliance | J45: Rare | K45: Text | L45: USER
A46: LKP_RECYCLABILITY_CLASS | B46: RECYCLABILITY_CLASS_ID | C46: INT | D46: Y | E46: Y | F46: N | H46: Recyclability class | I46: MDM + Compliance | J46: Rare | K46: PK unique; not blank when row used | L46: USER
A47: LKP_RECYCLABILITY_CLASS | B47: RECYCLABILITY_CLASS_CODE | C47: TEXT | D47: Y | E47: N | F47: N | H47: Recyclability class | I47: MDM + Compliance | J47: Rare | K47: Text | L47: USER
A48: LKP_RECYCLABILITY_CLASS | B48: RECYCLABILITY_CLASS_NAME | C48: TEXT | D48: Y | E48: N | F48: N | H48: Recyclability class | I48: MDM + Compliance | J48: Rare | K48: Text | L48: USER
A49: LKP_OWNERSHIP_TYPE | B49: OWNERSHIP_TYPE_ID | C49: INT | D49: Y | E49: Y | F49: N | H49: Disposable / returnable / pool (returnable architecture hook) | I49: MDM + Compliance | J49: Rare | K49: PK unique; not blank when row used | L49: USER
A50: LKP_OWNERSHIP_TYPE | B50: OWNERSHIP_TYPE_CODE | C50: TEXT | D50: Y | E50: N | F50: N | H50: Disposable / returnable / pool (returnable architecture hook) | I50: MDM + Compliance | J50: Rare | K50: Text | L50: USER
A51: LKP_OWNERSHIP_TYPE | B51: OWNERSHIP_TYPE_NAME | C51: TEXT | D51: Y | E51: N | F51: N | H51: Disposable / returnable / pool (returnable architecture hook) | I51: MDM + Compliance | J51: Rare | K51: Text | L51: USER
A52: LKP_TRANSPORT_UNIT_TYPE | B52: TRANSPORT_UNIT_TYPE_ID | C52: INT | D52: Y | E52: Y | F52: N | H52: Pallet / container / truck / … | I52: MDM + Compliance | J52: Rare | K52: PK unique; not blank when row used | L52: USER
A53: LKP_TRANSPORT_UNIT_TYPE | B53: TRANSPORT_UNIT_TYPE_CODE | C53: TEXT | D53: Y | E53: N | F53: N | H53: Pallet / container / truck / … | I53: MDM + Compliance | J53: Rare | K53: Text | L53: USER
A54: LKP_TRANSPORT_UNIT_TYPE | B54: TRANSPORT_UNIT_TYPE_NAME | C54: TEXT | D54: Y | E54: N | F54: N | H54: Pallet / container / truck / … | I54: MDM + Compliance | J54: Rare | K54: Text | L54: USER
A55: LKP_LINE_ROLE | B55: LINE_ROLE_ID | C55: INT | D55: Y | E55: Y | F55: N | H55: Configuration line roles | I55: MDM + Compliance | J55: Rare | K55: PK unique; not blank when row used | L55: USER
...

Sheet 04_IMPORT_GUIDE
A1: 04_IMPORT_GUIDE — Phase F migration order (do not import yet)
A3: Phase E does NOT import production data. Follow this order in Phase F:
A5: 1. Lookup tables (LKP_*) — already seeded in Phase E; extend codes if needed
A6: 2. Legal entities / external IDs (LEGAL_ENTITY, PERSON, SUPPLIER, CUSTOMER, PLANT)
A7: 3. Components (COMPONENT)
A8: 4. Component materials (COMPONENT_MATERIAL) — shares ≈ 100%
A9: 5. Products (PRODUCT)
A10: 6. Packaging configurations (PACKAGING_CONFIGURATION) — Golden Variant CONFIG_GROUP_CODE
A11: 7. Packaging configuration lines (PACKAGING_CONFIGURATION_LINE) — exact BOM
A12: 8. Transport configurations (+ lines)
A13: 9. Commercial scenarios (product → transport → packaging mapping)
A14: 10. Document / evidence metadata (DOCUMENT_LIBRARY, DOCUMENT_LINK, TF, DoC)
... A27: Article 5: do not auto-populate ≤100 mg/kg without evidence.

Sheet SYS_WORKBOOK_INFO
A1: INFO_KEY | B1: INFO_VALUE | C1: UPDATED_AT
A2: SCHEMA_VERSION | B2: 1.0.0 | C2: 2026-08-10T19:29:54Z
A3: WORKBOOK_NAME | B3: INCI_AKU_PPWR_PIMS_Rev00.xlsx | C3: 2026-08-10T19:29:54Z
A4: PROJECT_NAME | B4: INCI_AKU_PPWR_PIMS | C4: 2026-08-10T19:29:54Z
A5: REVISION | B5: Rev00 | C5: 2026-08-10T19:29:54Z
A6: PHASE | B6: F — Production Migration | C6: 2026-08-10T19:29:54Z
A7: PRODUCTION_DATA | B7: LOADED | C7: 2026-08-10T19:29:54Z
A8: WORD_GENERATION | B8: DISABLED | C8: 2026-08-10T19:29:54Z
A9: GENERATED_AT_UTC | B9: 2026-08-10T19:29:54Z | C9: 2026-08-10T19:29:54Z
A10: EXCEL_ENGINE | B10: openpyxl | C10: 2026-08-10T19:29:54Z
A11: CIP_CIF_NOTE | B11: CIF and CIP are distinct Incoterms; both active in LKP_INCOTERM | C11: 2026-08-10T19:29:54Z
A12: FINAL_CONFIG_COUNT | B12: 247 | C12: 247
A13: PHASE | B13: J — Application Layer + Document Registry Sync
A14: DOCUMENT_REGISTRY | B14: 988/988 LINKED

Sheet SYS_PARAMETER
A1: PARAMETER_ID | B1: PARAMETER_CODE | C1: PARAMETER_VALUE | D1: DESCRIPTION
A2: 1 | B2: WEIGHT_UOM | C2: G | D2: Mass unit for COMPONENT.WEIGHT_G
A3: 2 | B3: TRANSPORT_ALLOCATION_METHOD | C3: PER_PRODUCT_UNIT | D3: Transport-line weight allocation method
A4: 3 | B4: MATERIAL_SHARE_TOLERANCE_PCT | C4: 0.5 | D4: Allowed deviation from 100% material shares
A5: 4 | B5: ENABLE_WORD_GENERATION | C5: FALSE | D5: Document generation disabled in Phase E
A6: 5 | B6: PRODUCTION_DATA_LOADED | C6: FALSE | D6: Phase F loads production masters
A7: 6 | B7: ARTICLE5_BASIS_LABEL | C7: REV00 CURRENT EVIDENCE BASIS — ARTICLE 5 ASSESSMENT BASIS | D7: Controlled customer language — do not auto-fill numerical compliance

Sheet LKP_STATUS
A1: STATUS_ID | B1: STATUS_CODE | C1: STATUS_NAME | D1: STATUS_DOMAIN | E1: IS_EDITABLE | F1: SORT_ORDER
A2: 1 | B2: DRAFT | C2: Draft | D2: MASTER | E2: TRUE | F2: 1
A3: 2 | B3: ACTIVE | C3: Active | D3: MASTER | E3: TRUE | F3: 2
A4: 3 | B4: OBSOLETE | C4: Obsolete | D4: MASTER | E4: FALSE | F4: 3
A5: 4 | B5: CONFIRMED | C5: Confirmed | D5: SHIPMENT | E5: FALSE | F5: 4
A6: 5 | B6: CANCELLED | C6: Cancelled | D6: SHIPMENT | E6: FALSE | F6: 5
A7: 6 | B7: APPROVED_DOC | C7: Approved (Document) | D7: DOCUMENT | E7: FALSE | F7: 6
