Workbook
Name NR_COMMERCIAL_SCENARIO_ID: COMMERCIAL_SCENARIO!$A$2:$A$5000
Name NR_COMPONENT_ID: COMPONENT!$A$2:$A$5000
Name NR_COMPONENT_MATERIAL_ID: COMPONENT_MATERIAL!$A$2:$A$5000
Name NR_COMPONENT_TYPE_ID: LKP_COMPONENT_TYPE!$A$2:$A$5000
Name NR_COUNTRY_ID: LKP_COUNTRY!$A$2:$A$5000
Name NR_CUSTOMER_ID: CUSTOMER!$A$2:$A$5000
Name NR_DECLARATION_OF_CONFORMITY_ID: DECLARATION_OF_CONFORMITY!$A$2:$A$5000
Name NR_DOCUMENT_ID: DOCUMENT_LIBRARY!$A$2:$A$5000
Name NR_DOCUMENT_LINK_ID: DOCUMENT_LINK!$A$2:$A$5000
Name NR_DOCUMENT_TYPE_ID: LKP_DOCUMENT_TYPE!$A$2:$A$5000
Name NR_INCOTERM_ID: LKP_INCOTERM!$A$2:$A$5000
Name NR_INFO_KEY: SYS_WORKBOOK_INFO!$A$2:$A$5000
Name NR_LEGAL_ENTITY_ID: LEGAL_ENTITY!$A$2:$A$5000
Name NR_LINE_ROLE_ID: LKP_LINE_ROLE!$A$2:$A$5000
Name NR_MATERIAL_FAMILY_ID: LKP_MATERIAL_FAMILY!$A$2:$A$5000
Name NR_MATERIAL_ID: LKP_MATERIAL!$A$2:$A$5000
Name NR_OWNERSHIP_TYPE_ID: LKP_OWNERSHIP_TYPE!$A$2:$A$5000
Name NR_PACKAGING_CONFIGURATION_ID: PACKAGING_CONFIGURATION!$A$2:$A$5000
Name NR_PACKAGING_CONFIGURATION_LINE_ID: PACKAGING_CONFIGURATION_LINE!$A$2:$A$5000
Name NR_PACKAGING_FUNCTION_ID: LKP_PACKAGING_FUNCTION!$A$2:$A$5000
Name NR_PACKAGING_LEVEL_ID: LKP_PACKAGING_LEVEL!$A$2:$A$5000
Name NR_PARAMETER_ID: SYS_PARAMETER!$A$2:$A$5000
Name NR_PERSON_ID: PERSON!$A$2:$A$5000
Name NR_PLANT_ID: PLANT!$A$2:$A$5000
Name NR_PPWR_MATERIAL_CATEGORY_ID: LKP_PPWR_MATERIAL_CATEGORY!$A$2:$A$5000
Name NR_PRODUCT_CATEGORY_ID: LKP_PRODUCT_CATEGORY!$A$2:$A$5000
Name NR_PRODUCT_ID: PRODUCT!$A$2:$A$5000
Name NR_RECYCLABILITY_CLASS_ID: LKP_RECYCLABILITY_CLASS!$A$2:$A$5000
Name NR_SCENARIO_TYPE_ID: LKP_SCENARIO_TYPE!$A$2:$A$5000
Name NR_SHIPMENT_ID: SHIPMENT!$A$2:$A$5000
Name NR_SHIPMENT_LINE_ID: SHIPMENT_LINE!$A$2:$A$5000
Name NR_STATEMENT_ID: STATEMENT!$A$2:$A$5000
Name NR_STATEMENT_LINE_ID: STATEMENT_LINE!$A$2:$A$5000
Name NR_STATEMENT_SHIPMENT_ID: STATEMENT_SHIPMENT!$A$2:$A$5000
Name NR_STATEMENT_TYPE_ID: LKP_STATEMENT_TYPE!$A$2:$A$5000
Name NR_STATUS_ID: LKP_STATUS!$A$2:$A$5000
Name NR_SUPPLIER_ID: SUPPLIER!$A$2:$A$5000
Name NR_TECHNICAL_FILE_ID: TECHNICAL_FILE!$A$2:$A$5000
Name NR_TRANSPORT_CONFIGURATION_ID: TRANSPORT_CONFIGURATION!$A$2:$A$5000
Name NR_TRANSPORT_CONFIGURATION_LINE_ID: TRANSPORT_CONFIGURATION_LINE!$A$2:$A$5000
Name NR_TRANSPORT_MODE_ID: LKP_TRANSPORT_MODE!$A$2:$A$5000
Name NR_TRANSPORT_UNIT_TYPE_ID: LKP_TRANSPORT_UNIT_TYPE!$A$2:$A$5000
Name NR_UOM_ID: LKP_UOM!$A$2:$A$5000

Sheet 00_HOME
A1: İnci Akü PPWR Packaging Information Management System — Rev.00
A2: Production Master Data: LOADED | Golden Variant Register: 247 / 247 | Document Pack: 988 / 988 GENERATED | Document Registry: 988 / 988 LINKED | Blocking QA Errors: 0
A3: Legal signatures are NOT completed in this workbook. Word files remain the controlled legal documents.
A5: KPI | B5: Count | C5: Status
A6: Final Packaging Configurations | B6: 247 | C6: LOADED
A7: Starter | B7: 240 | C7: LOADED
A8: Industrial | B8: 3 | C8: LOADED
A9: Container / Loading | B9: 4 | C9: LOADED
A10: BOM Lines | B10: 1690 | C10: LOADED
A11: Components | B11: 112 | C11: LOADED
A12: Products | B12: 2046 | C12: LOADED
A13: Technical Files | B13: 247 | C13: GENERATED
A14: EU Declarations of Conformity | B14: 247 | C14: GENERATED
A15: Labels | B15: 247 | C15: GENERATED
A16: Shipment Statements | B16: 247 | C16: GENERATED
A17: Total Documents | B17: 988 | C17: GENERATED
A18: Document Registry Linked | B18: 988 / 988 | C18: LINKED
A19: Blocking QA Errors | B19: 0 | C19: PASS
A22: Quick navigation
A23: =HYPERLINK("#'PACKAGING_CONFIGURATIONS'!A1","Packaging Configurations")
A24: =HYPERLINK("#'PRODUCT_MASTER'!A1","Products")
A25: =HYPERLINK("#'COMPONENT_MASTER'!A1","Components")
A26: =HYPERLINK("#'TECHNICAL_FILES'!A1","Technical Files")
A27: =HYPERLINK("#'DECLARATIONS_OF_CONFORMITY'!A1","Declarations of Conformity")
A28: =HYPERLINK("#'LABELS'!A1","Labels")
A29: =HYPERLINK("#'SHIPMENT_STATEMENTS'!A1","Shipment Statements")
A30: =HYPERLINK("#'DOCUMENT_CENTER'!A1","Document Center")
A31: =HYPERLINK("#'SEARCH'!A1","Search")
A32: =HYPERLINK("#'NAVIGATION'!A1","Navigation")

Sheet NAVIGATION
A1: NAVIGATION
A3: HOME
A4: =HYPERLINK("#'00_HOME'!A1","00_HOME")
A5: =HYPERLINK("#'01_DASHBOARD'!A1","01_DASHBOARD")
A6: =HYPERLINK("#'02_RELEASE_CONTROL'!A1","02_RELEASE_CONTROL")
A8: PACKAGING
A9: =HYPERLINK("#'PACKAGING_CONFIGURATIONS'!A1","PACKAGING_CONFIGURATIONS")
A11: PRODUCTS
A12: =HYPERLINK("#'PRODUCT_MASTER'!A1","PRODUCT_MASTER")
A14: COMPONENTS
A15: =HYPERLINK("#'COMPONENT_MASTER'!A1","COMPONENT_MASTER")
A17: DOCUMENTS
A18: =HYPERLINK("#'DOCUMENT_CENTER'!A1","DOCUMENT_CENTER")
A19: =HYPERLINK("#'TECHNICAL_FILES'!A1","TECHNICAL_FILES")
A20: =HYPERLINK("#'DECLARATIONS_OF_CONFORMITY'!A1","DECLARATIONS_OF_CONFORMITY")
A21: =HYPERLINK("#'LABELS'!A1","LABELS")
A22: =HYPERLINK("#'SHIPMENT_STATEMENTS'!A1","SHIPMENT_STATEMENTS")
A24: OPERATIONS
A25: =HYPERLINK("#'SHIPMENTS'!A1","SHIPMENTS")
A26: =HYPERLINK("#'SEARCH'!A1","SEARCH")
A28: DATABASE
A29: =HYPERLINK("#'PACKAGING_CONFIGURATION'!A1","PACKAGING_CONFIGURATION")
A30: =HYPERLINK("#'PACKAGING_CONFIGURATION_LINE'!A1","PACKAGING_CONFIGURATION_LINE")
A31: =HYPERLINK("#'PRODUCT'!A1","PRODUCT")
A32: =HYPERLINK("#'COMPONENT'!A1","COMPONENT")
A33: =HYPERLINK("#'DOCUMENT_LIBRARY'!A1","DOCUMENT_LIBRARY")
A34: =HYPERLINK("#'DOCUMENT_LINK'!A1","DOCUMENT_LINK")
A36: LOOKUPS
A37: =HYPERLINK("#'LKP_STATUS'!A1","LKP_STATUS")
A38: =HYPERLINK("#'LKP_DOCUMENT_TYPE'!A1","LKP_DOCUMENT_TYPE")
A39: =HYPERLINK("#'LKP_MATERIAL_FAMILY'!A1","LKP_MATERIAL_FAMILY")
A41: SYSTEM
A42: =HYPERLINK("#'SYS_WORKBOOK_INFO'!A1","SYS_WORKBOOK_INFO")
A43: =HYPERLINK("#'DOC_ENGINE_MAP'!A1","DOC_ENGINE_MAP")
A44: =HYPERLINK("#'00_README'!A1","00_README")

Sheet SEARCH
A1: SEARCH
A2: Use AutoFilter on DOCUMENT_CENTER / PACKAGING_CONFIGURATIONS / TECHNICAL_FILES (or Ctrl+F). Optional single-key lookup below uses XLOOKUP when available.
A4: Lookup key
A5: Examples | B5: ST-051-STD-01 | IA-ST-051-STD-01 | IA-ST-CFG-0122 | IA-PPWR-TF-ST-051-STD-01-R00 | 1011935 | 4000782
A7: Packaging Set → Configuration ID
A8: Configuration ID | B8: =IF(B4="","",IFERROR(XLOOKUP(B4,PACKAGING_CONFIGURATIONS!A:A,PACKAGING_CONFIGURATIONS!B:B),"Not found / use AutoFilter"))
A9: Family | B9: =IF(B4="","",IFERROR(XLOOKUP(B4,PACKAGING_CONFIGURATIONS!A:A,PACKAGING_CONFIGURATIONS!D:D),""))
A10: Technical File | B10: =IF(B4="","",IFERROR(XLOOKUP(B4,PACKAGING_CONFIGURATIONS!A:A,PACKAGING_CONFIGURATIONS!K:K),""))
A12: Module shortcuts
A13: =HYPERLINK("#'DOCUMENT_CENTER'!A1","Document Center (filter here)")
A14: =HYPERLINK("#'PACKAGING_CONFIGURATIONS'!A1","Packaging Configurations")
A15: =HYPERLINK("#'TECHNICAL_FILES'!A1","Technical Files")
A16: =HYPERLINK("#'PRODUCT_MASTER'!A1","Product Master")
A17: =HYPERLINK("#'COMPONENT_MASTER'!A1","Component Master")

Sheet PACKAGING_CONFIGURATIONS
A1: Packaging Set Code | B1: Final Configuration ID | C1: Source Configuration ID | D1: Family | E1: Packaging Description | F1: Variant Basis TR | G1: Variant Basis EN | H1: Packaging Tare kg | I1: Product Count | J1: BOM Line Count | K1: Technical File | L1: DoC | M1: Label | N1: Statement
A2: CNT-20-EUR-01 | B2: IA-CNT-20-EUR-01 | C2: IA-CNT-20-EUR | D2: CONTAINER | E2: Container loading | OSB (5501806): 11 adet | Separatör (4000130): 10 adet | F2: Container loading | OSB (5501806): 11 adet | Separatör (4000130): 10 adet | G2: Container loading | OSB (5501806): 11 pcs | Separator (4000130): 10 pcs | H2: 83.06 | I2: 0 | J2: 8 | K2: IA-PPWR-TF-CNT-20-EUR-01-R00 | L2: IA-PPWR-DOC-CNT-20-EUR-01-R00 | M2: IA-PPWR-LBL-CNT-20-EUR-01-R00 | N2: IA-PPWR-STM-CNT-20-EUR-01-R00
A3: CNT-20-STD-01 | B3: IA-CNT-20-STD-01 | C3: IA-CNT-20-STD | D3: CONTAINER | E3: Container loading | OSB (5501805): 10 adet | Separatör (4000130): 10 adet | F3: Container loading | OSB (5501805): 10 adet | Separatör (4000130): 10 adet | G3: Container loading | OSB (5501805): 10 pcs | Separator (4000130): 10 pcs | H3: 78.06 | I3: 0 | J3: 8 | K3: IA-PPWR-TF-CNT-20-STD-01-R00 | L3: IA-PPWR-DOC-CNT-20-STD-01-R00 | M3: IA-PPWR-LBL-CNT-20-STD-01-R00 | N3: IA-PPWR-STM-CNT-20-STD-01-R00
A4: CNT-40-IND-01 | B4: IA-CNT-40-IND-01 | C4: IA-CNT-40-IND | D4: CONTAINER | E4: Container loading | Hava yastığı (5500759): 26 adet | Bağlama halatı (5500762): 12 m | F4: Container loading | Hava yastığı (5500759): 26 adet | Bağlama halatı (5500762): 12 m | G4: Container loading | Air dunnage (5500759): 26 pcs | Lashing rope (5500762): 12 m | H4: 12.76 | I4: 0 | J4: 5 | K4: IA-PPWR-TF-CNT-40-IND-01-R00 | L4: IA-PPWR-DOC-CNT-40-IND-01-R00 | M4: IA-PPWR-LBL-CNT-40-IND-01-R00 | N4: IA-PPWR-STM-CNT-40-IND-01-R00
A5: CNT-DE-HAM-01 | B5: IA-CNT-DE-HAM-01 | C5: IA-CNT-DE-HAMBURG | D5: CONTAINER | E5: Container loading | Sabitleme Tahtası ( 206×9×9 ) (Hamburg): 2 adet | F5: Container loading | Sabitleme Tahtası ( 206×9×9 ) (Hamburg): 2 adet | G5: Container loading | Sabitleme Tahtası ( 206×9×9 ) (Hamburg): 2 pcs | H5: 194 | I5: 0 | J5: 3 | K5: IA-PPWR-TF-CNT-DE-HAM-01-R00 | L5: IA-PPWR-DOC-CNT-DE-HAM-01-R00 | M5: IA-PPWR-LBL-CNT-DE-HAM-01-R00 | N5: IA-PPWR-STM-CNT-DE-HAM-01-R00
A6: IND-24V-01 | B6: IA-IND-24V-01 | C6: IA-IND-24V | D6: INDUSTRIAL | E6: 24V | Palet (4001005): 1 adet | F6: 24V | Palet (4001005): 1 adet | G6: 24V | Pallet (4001005): 1 pc | H6: 27.388 | I6: 0 | J6: 6 | K6: IA-PPWR-TF-IND-24V-01-R00 | L6: IA-PPWR-DOC-IND-24V-01-R00 | M6: IA-PPWR-LBL-IND-24V-01-R00 | N6: IA-PPWR-STM-IND-24V-01-R00
A7: IND-48V-01 | B7: IA-IND-48V-01 | C7: IA-IND-48V | D7: INDUSTRIAL | E7: 48V | Palet (4001005): 1 adet | F7: 48V | Palet (4001005): 1 adet | G7: 48V | Pallet (4001005): 1 pc | H7: 27.5767 | I7: 0 | J7: 6 | K7: IA-PPWR-TF-IND-48V-01-R00 | L7: IA-PPWR-DOC-IND-48V-01-R00 | M7: IA-PPWR-LBL-IND-48V-01-R00 | N7: IA-PPWR-STM-IND-48V-01-R00
A8: IND-80V-01 | B8: IA-IND-80V-01 | C8: IA-IND-80V | D8: INDUSTRIAL | E8: 80V | Palet (4000973): 1 adet | F8: 80V | Palet (4000973): 1 adet | G8: 80V | Pallet (4000973): 1 pc | H8: 32.63147 | I8: 0 | J8: 6 | K8: IA-PPWR-TF-IND-80V-01-R00 | L8: IA-PPWR-DOC-IND-80V-01-R00 | M8: IA-PPWR-LBL-IND-80V-01-R00 | N8: IA-PPWR-STM-IND-80V-01-R00
A9: ST-012-EUR-01 | B9: IA-ST-012-EUR-01 | C9: IA-ST-CFG-0004 | D9: STARTER | E9: C | Palet (4000038): 1 adet | Köşebent (4000590): 4 adet | F9: C | Palet (4000038): 1 adet | Köşebent (4000590): 4 adet | G9: C | Pallet (4000038): 1 pc | Edge protector (4000590): 4 pcs | H9: 29.326 | I9: 1 | J9: 7 | K9: IA-PPWR-TF-ST-012-EUR-01-R00 | L9: IA-PPWR-DOC-ST-012-EUR-01-R00 | M9: IA-PPWR-LBL-ST-012-EUR-01-R00 | N9: IA-PPWR-STM-ST-012-EUR-01-R00
A10: ST-012-EUR-02 | B10: IA-ST-012-EUR-02 | C10: IA-ST-CFG-0005 | D10: STARTER | E10: L6 | Palet (4000038): 1 adet | Köşebent (4000590): 4 adet | F10: L6 | Palet (4000038): 1 adet | Köşebent (4000590): 4 adet | G10: L6 | Pallet (4000038): 1 pc | Edge protector (4000590): 4 pcs | H10: 27.526 | I10: 1 | J10: 6 | K10: IA-PPWR-TF-ST-012-EUR-02-R00 | L10: IA-PPWR-DOC-ST-012-EUR-02-R00 | M10: IA-PPWR-LBL-ST-012-EUR-02-R00 | N10: IA-PPWR-STM-ST-012-EUR-02-R00
A11: ST-012-EUR-03 | B11: IA-ST-012-EUR-03 | C11: IA-ST-CFG-0006 | D11: STARTER | E11: C | Palet (4000038): 1 adet | Köşebent (4000590): 2 adet | F11: C | Palet (4000038): 1 adet | Köşebent (4000590): 2 adet | G11: C | Pallet (4000038): 1 pc | Edge protector (4000590): 2 pcs | H11: 29.0392 | I11: 2 | J11: 7 | K11: IA-PPWR-TF-ST-012-EUR-03-R00 | L11: IA-PPWR-DOC-ST-012-EUR-03-R00 | M11: IA-PPWR-LBL-ST-012-EUR-03-R00 | N11: IA-PPWR-STM-ST-012-EUR-03-R00
A12: ST-018-EUR-01 | B12: IA-ST-018-EUR-01 | C12: IA-ST-CFG-0012 | D12: STARTER | E12: C | Palet (4000038): 1 adet | Köşebent (4001160): 4 adet | F12: C | Palet (4000038): 1 adet | Köşebent (4001160): 4 adet | G12: C | Pallet (4000038): 1 pc | Edge protector (4001160): 4 pcs | H12: 32.434 | I12: 1 | J12: 9 | K12: IA-PPWR-TF-ST-018-EUR-01-R00 | L12: IA-PPWR-DOC-ST-018-EUR-01-R00 | M12: IA-PPWR-LBL-ST-018-EUR-01-R00 | N12: IA-PPWR-STM-ST-018-EUR-01-R00
A13: ST-018-EUR-02 | B13: IA-ST-018-EUR-02 | C13: IA-ST-CFG-0013 | D13: STARTER | E13: C | Palet (4000038): 1 adet | Köşebent (4000590): 4 adet | F13: C | Palet (4000038): 1 adet | Köşebent (4000590): 4 adet | G13: C | Pallet (4000038): 1 pc | Edge protector (4000590): 4 pcs | H13: 30.194 | I13: 4 | J13: 7 | K13: IA-PPWR-TF-ST-018-EUR-02-R00 | L13: IA-PPWR-DOC-ST-018-EUR-02-R00 | M13: IA-PPWR-LBL-ST-018-EUR-02-R00 | N13: IA-PPWR-STM-ST-018-EUR-02-R00
... A248: ST-120-STD-03 | B248: IA-ST-120-STD-03 | C248: IA-ST-CFG-0286 | D248: STARTER | E248: NS40 | Palet (4000037): 1 adet | Shrink film (4001177): 0.597 kg | F248: NS40 | Palet (4000037): 1 adet | Shrink film (4001177): 0.597 kg | G248: NS40 | Pallet (4000037): 1 pc | Shrink film (4001177): 0.597 kg | H248: 28.649 | I248: 4 | J248: 7 | K248: IA-PPWR-TF-ST-120-STD-03-R00 | L248: IA-PPWR-DOC-ST-120-STD-03-R00 | M248: IA-PPWR-LBL-ST-120-STD-03-R00 | N248: IA-PPWR-STM-ST-120-STD-03-R00

Sheet PRODUCT_MASTER
A1: Product Code | B1: Technical Description | C1: Category | D1: Mapped Packaging Set Code | E1: Configuration ID | F1: Source Configuration ID | G1: Packaging Tare | H1: Document Pack Status
A2: 1000069 | B2: AKÜ,C-FLAT,DK,200AH,İNCİ SUPRA SENTOR | C2: 1 | D2: ST-021-STD-03 | E2: IA-ST-021-STD-03 | F2: IA-ST-CFG-0023 | G2: 31.8252 | H2: 988-pack GENERATED
A3: 1000441 | B3: AKÜ,A-FLAT,DK,120AH,EAS PRIDE,İÇ PYS | C3: 1 | D3: ST-030-STD-08 | E3: IA-ST-030-STD-08 | F3: IA-ST-CFG-0054 | G3: 31.4124 | H3: 988-pack GENERATED
A4: 1000442 | B4: AKÜ,A-FLAT,DK,135AH,EAS PRIDE,İÇ PYS | C4: 1 | D4: ST-030-STD-08 | E4: IA-ST-030-STD-08 | F4: IA-ST-CFG-0054 | G4: 31.4124 | H4: 988-pack GENERATED
A5: 1000445 | B5: AKÜ,B-FLAT,DK,180AH,EAS PRIDE,İÇ PYS | C5: 1 | D5: ST-030-STD-09 | E5: IA-ST-030-STD-09 | F5: IA-ST-CFG-0055 | G5: 32.1024 | H5: 988-pack GENERATED
A6: 1000448 | B6: AKÜ,C-FLAT,DK,200AH,EAS PRIDE,İÇ PYS | C6: 1 | D6: ST-021-STD-04 | E6: IA-ST-021-STD-04 | F6: IA-ST-CFG-0024 | G6: 31.5384 | H6: 988-pack GENERATED
A7: 1000890 | B7: AKÜ,A-FLAT,DK,120AH,İNCİ SUPRA SENTOR | C7: 1 | D7: ST-030-STD-05 | E7: IA-ST-030-STD-05 | F7: IA-ST-CFG-0051 | G7: 31.6992 | H7: 988-pack GENERATED
A8: 1001102 | B8: AKÜ,C-FLAT,DK,225AH,EAS PRIDE,İÇ PYS | C8: 1 | D8: ST-021-STD-04 | E8: IA-ST-021-STD-04 | F8: IA-ST-CFG-0024 | G8: 31.5384 | H8: 988-pack GENERATED
A9: 1002103 | B9: AKÜ,TRAKTÖRL,DK,115AH,EAS PRIDE,İÇ PYS | C9: 1 | D9: ST-045-STD-09 | E9: IA-ST-045-STD-09 | F9: IA-ST-CFG-0097 | G9: 33.063 | H9: 988-pack GENERATED
A10: 1002104 | B10: AKÜ,TRAKTÖR,DK,125AH,EAS PRIDE,İÇ PYS | C10: 1 | D10: ST-045-STD-09 | E10: IA-ST-045-STD-09 | F10: IA-ST-CFG-0097 | G10: 33.063 | H10: 988-pack GENERATED
A11: 1002216 | B11: AKÜ,B-FLAT,DK,180AH,İNCİ SUPRA,EEC MISIR | C11: 1 | D11: ST-030-STD-06 | E11: IA-ST-030-STD-06 | F11: IA-ST-CFG-0052 | G11: 32.3892 | H11: 988-pack GENERATED
A12: 1002422 | B12: AKÜ,B-FLAT,DK,170AH,HUGEL ACTION | C12: 1 | D12: ST-030-STD-06 | E12: IA-ST-030-STD-06 | F12: IA-ST-CFG-0052 | G12: 32.3892 | H12: 988-pack GENERATED
A13: 1002873 | B13: AKÜ,A-FLAT,DK,135AH,HUGEL ACTION | C13: 1 | D13: ST-030-STD-05 | E13: IA-ST-030-STD-05 | F13: IA-ST-CFG-0051 | G13: 31.6992 | H13: 988-pack GENERATED
... A34: 1004497 | B34: AKÜ,A-FLAT,DK,135AH,BLIZZARO TRENDLINE | C34: 1 | D34: ST-030-STD-05 | E34: IA-ST-030-STD-05 | F34: IA-ST-CFG-0051 | G34: 31.6992 | H34: 988-pack GENERATED
A35: 1004590 | B35: AKÜ,TRACTOR,DK,125AH,B00,SUPRA,AIOS OEM | C35: 1 | H35: NO MAPPING
A36: 1004591 | B36: AKÜ,TRACTORL,DK,105AH,B01,SUPRA,AIOS OEM | C36: 1 | H36: NO MAPPING
A37: 1004599 | B37: AKÜ,TRACTORL,DK,115AH,B00,İNCİSUPR,TEMSA | C37: 1 | H37: NO MAPPING
A38: 1004600 | B38: AKÜ,TRACTORL,DK,105AH,İNCİSUPRA,TEMSAOEM | C38: 1 | H38: NO MAPPING
A39: 1005175 | B39: AKÜ,B-FLAT,DK,180AH,İNCİ SUPRA SENT,EURO | C39: 1 | D39: ST-021-EUR-03 | E39: IA-ST-021-EUR-03 | F39: IA-ST-CFG-0029 | G39: 30.7682 | H39: 988-pack GENERATED
A40: 1005176 | B40: AKÜ,C-FLAT,DK,225AH,İNCİ SUPRA SENT,EURO | C40: 1 | D40: ST-018-EUR-03 | E40: IA-ST-018-EUR-03 | F40: IA-ST-CFG-0014 | G40: 30.9872 | H40: 988-pack GENERATED
A41: 1005491 | B41: AKÜ,TRACTORL,DK,105AH,CARGO,MAKO,OES | C41: 1 | H41: NO MAPPING
A42: 1005780 | B42: AKÜ,C-IGYA,DK,225AH,İNCİ SUPRA,TEMSA OEM | C42: 1 | H42: NO MAPPING
A43: 1005826 | B43: AKÜ,C-IGYA,DK,210AH,İNCİ SUPRASENTOR,BMC | C43: 1 | H43: NO MAPPING
A44: 1005827 | B44: AKÜ,C-IGYA,DK,225AH,İNCİ SUPRA,BMC,HORT | C44: 1 | H44: NO MAPPING
A45: 1005828 | B45: AKÜ,B-FLAT,DK,180AH,İNCİ SUPRASENTOR,BMC | C45: 1 | H45: NO MAPPING
A46: 1005829 | B46: AKÜ,B-IGYA,DK,180AH,SUPRA,BMCOTOBÜS,HORT | C46: 1 | H46: NO MAPPING
A47: 1005833 | B47: AKÜ,TRACTORL,DK,115AH,B01,SUPRA,ERKUNT | C47: 1 | H47: NO MAPPING
A48: 1005922 | B48: AKÜ,TRACTORL,DK,105AH,B01,SUPRA,ERKUNT | C48: 1 | H48: NO MAPPING
A49: 1006036 | B49: AKÜ,A-FLAT,DK,135AH,CARGO,MAKO,OES | C49: 1 | H49: NO MAPPING
A50: 1006037 | B50: AKÜ,B-FLAT,DK,150AH,CARGO,MAKO,OES | C50: 1 | H50: NO MAPPING
A51: 1006039 | B51: AKÜ,B-FLAT,DK,180AH,CARGO,MAKO,OES | C51: 1 | H51: NO MAPPING
A52: 1006040 | B52: AKÜ,C-FLAT,DK,200AH,CARGO,MAKO,OES | C52: 1 | D52: ST-018-EUR-05 | E52: IA-ST-018-EUR-05 | F52: IA-ST-CFG-0016 | G52: 30.7004 | H52: 988-pack GENERATED
A53: 1006041 | B53: AKÜ,C-FLAT,DK,225AH,CARGO,MAKO,OES | C53: 1 | D53: ST-018-EUR-05 | E53: IA-ST-018-EUR-05 | F53: IA-ST-CFG-0016 | G53: 30.7004 | H53: 988-pack GENERATED
A54: 1006054 | B54: AKÜ,C-IGYA,DK,240AH,İNCİ SUPRASENTOR,BMC | C54: 1 | H54: NO MAPPING
A55: 1006077 | B55: AKÜ,A-IGYASMF,DK,120AH,İNCİFORMULATAURUS | C55: 1 | D55: ST-030-STD-05 | E55: IA-ST-030-STD-05 | F55: IA-ST-CFG-0051 | G55: 31.6992 | H55: 988-pack GENERATED
A56: 1006081 | B56: AKÜ,A-IGYASMF,DK,135AH,İNCİFORMULATAURUS | C56: 1 | D56: ST-030-STD-05 | E56: IA-ST-030-STD-05 | F56: IA-ST-CFG-0051 | G56: 31.6992 | H56: 988-pack GENERATED
A57: 1006083 | B57: AKÜ,A-IGYASMF,DK,140AH,İNCİFORMULATAURUS | C57: 1 | D57: ST-030-STD-05 | E57: IA-ST-030-STD-05 | F57: IA-ST-CFG-0051 | G57: 31.6992 | H57: 988-pack GENERATED
A58: 1006152 | B58: AKÜ,B-IGYASMF,DK150AH,FORMULA,EEC MISIR | C58: 1 | D58: ST-030-STD-06 | E58: IA-ST-030-STD-06 | F58: IA-ST-CFG-0052 | G58: 32.3892 | H58: 988-pack GENERATED
A59: 1006165 | B59: AKÜ,B-IGYASMF,DK,150AH,HUGEL ULTRA | C59: 1 | D59: ST-030-STD-06 | E59: IA-ST-030-STD-06 | F59: IA-ST-CFG-0052 | G59: 32.3892 | H59: 988-pack GENERATED
A60: 1006428 | B60: AKÜ,B-FLAT,DK,165AH,BLIZARO TREND,JANENE | C60: 1 | D60: ST-030-STD-06 | E60: IA-ST-030-STD-06 | F60: IA-ST-CFG-0052 | G60: 32.3892 | H60: 988-pack GENERATED
...

Sheet COMPONENT_MASTER
A1: ERP Component Code | B1: Description | C1: Component Type | D1: Material Family | E1: UOM | F1: Controlled Unit Weight (g) | G1: Supplier | H1: Evidence Status | I1: Configs Using Component
A2: 3503036 | B2: END OTO DOLUM SAF SU BIDONU 25L | C2: 14 | E2: ADT | F2: 1140 | H2: See evidence archive | I2: 1
A3: 3506099 | B3: END OTO DOLUM SAF SU BIDONU 20L | C3: 14 | E3: ADT | F3: 1140 | H3: See evidence archive | I3: 2
A4: 4000033 | B4: KARTON KÖŞEBENT,4cm*4cm*4*100cm,SEVPLT | C4: 14 | E4: ADT | F4: 210 | H4: See evidence archive | I4: 78
A5: 4000035 | B5: STRECH,23MC,50CM*300M | C5: 14 | E5: ADT | F5: 14.85 | H5: See evidence archive | I5: 3
A6: 4000037 | B6: PALET STANDART,1030*1110*152 | C6: 14 | E6: ADT | F6: 26000 | H6: See evidence archive | I6: 150
A7: 4000038 | B7: PALET EURO,800*1200*152 | C7: 14 | E7: ADT | F7: 26000 | H7: See evidence archive | I7: 88
A8: 4000130 | B8: KARTON SEPERATÖR,102*105,B DALGA | C8: 14 | E8: ADT | F8: 270 | H8: See evidence archive | I8: 154
A9: 4000300 | B9: STRECH,23MC,50CM*1500M,MAKİNA STRECH | C9: 14 | E9: ADT | F9: 18.32 | H9: See evidence archive | I9: 240
A10: 4000301 | B10: STRECH PED,80MC,140CM*170CM | C10: 14 | E10: ADT | F10: 1000 | H10: See evidence archive | I10: 221
A11: 4000350 | B11: PALET STANDART 100*90 CM | C11: 14 | E11: ADT | F11: 20000 | H11: See evidence archive | I11: 2
A12: 4000370 | B12: STRAFOR,1050*1000*40,TABAKA,STANDART | C12: 14 | E12: ADT | F12: 104 | H12: See evidence archive | I12: 10
A13: 4000440 | B13: D26,VAKUM PVC,ÜST KAPAK | C13: 14 | E13: ADT | F13: 64 | H13: See evidence archive | I13: 4
... A113: IND-LABELS | B113: Tüm Etiketler | C113: 14 | E113: ADT | F113: 5 | H113: See evidence archive | I113: 3

Sheet DOCUMENT_CENTER
A1: Packaging Set Code | B1: Configuration ID | C1: Variant Basis TR | D1: Variant Basis EN | E1: Source BOM ID | F1: Family | G1: Packaging Tare kg | H1: Product Count | I1: Technical File ID | J1: Open Technical File | K1: EU DoC ID | L1: Open EU DoC | M1: Label ID | N1: Open Label | O1: Statement ID | P1: Open Statement | Q1: Document Status | R1: Revision
A2: CNT-20-EUR-01 | B2: IA-CNT-20-EUR-01 | C2: Container loading | OSB (5501806): 11 adet | Separatör (4000130): 10 adet | D2: Container loading | OSB (5501806): 11 pcs | Separator (4000130): 10 pcs | E2: IA-CNT-20-EUR | F2: CONTAINER | G2: 83.06 | H2: 0 | I2: IA-PPWR-TF-CNT-20-EUR-01-R00 | J2: =HYPERLINK("03_CONTAINER/CNT-20-EUR-01/01_Technical_File.docx","Open") | K2: IA-PPWR-DOC-CNT-20-EUR-01-R00 | L2: =HYPERLINK("03_CONTAINER/CNT-20-EUR-01/02_EU_DoC.docx","Open") | M2: IA-PPWR-LBL-CNT-20-EUR-01-R00 | N2: =HYPERLINK("03_CONTAINER/CNT-20-EUR-01/03_Label.docx","Open") | O2: IA-PPWR-STM-CNT-20-EUR-01-R00 | P2: =HYPERLINK("03_CONTAINER/CNT-20-EUR-01/04_Shipment_Statement.docx","Open") | Q2: GENERATED / LINKED | R2: Rev.00
A3: CNT-20-STD-01 | B3: IA-CNT-20-STD-01 | C3: Container loading | OSB (5501805): 10 adet | Separatör (4000130): 10 adet | D3: Container loading | OSB (5501805): 10 pcs | Separator (4000130): 10 pcs | E3: IA-CNT-20-STD | F3: CONTAINER | G3: 78.06 | H3: 0 | I3: IA-PPWR-TF-CNT-20-STD-01-R00 | J3: =HYPERLINK("03_CONTAINER/CNT-20-STD-01/01_Technical_File.docx","Open") | K3: IA-PPWR-DOC-CNT-20-STD-01-R00 | L3: =HYPERLINK("03_CONTAINER/CNT-20-STD-01/02_EU_DoC.docx","Open") | M3: IA-PPWR-LBL-CNT-20-STD-01-R00 | N3: =HYPERLINK("03_CONTAINER/CNT-20-STD-01/03_Label.docx","Open") | O3: IA-PPWR-STM-CNT-20-STD-01-R00 | P3: =HYPERLINK("03_CONTAINER/CNT-20-STD-01/04_Shipment_Statement.docx","Open") | Q3: GENERATED / LINKED | R3: Rev.00
A4: CNT-40-IND-01 | B4: IA-CNT-40-IND-01 | C4: Container loading | Hava yastığı (5500759): 26 adet | Bağlama halatı (5500762): 12 m | D4: Container loading | Air dunnage (5500759): 26 pcs | Lashing rope (5500762): 12 m | E4: IA-CNT-40-IND | F4: CONTAINER | G4: 12.76 | H4: 0 | I4: IA-PPWR-TF-CNT-40-IND-01-R00 | J4: =HYPERLINK("03_CONTAINER/CNT-40-IND-01/01_Technical_File.docx","Open") | K4: IA-PPWR-DOC-CNT-40-IND-01-R00 | L4: =HYPERLINK("03_CONTAINER/CNT-40-IND-01/02_EU_DoC.docx","Open") | M4: IA-PPWR-LBL-CNT-40-IND-01-R00 | N4: =HYPERLINK("03_CONTAINER/CNT-40-IND-01/03_Label.docx","Open") | O4: IA-PPWR-STM-CNT-40-IND-01-R00 | P4: =HYPERLINK("03_CONTAINER/CNT-40-IND-01/04_Shipment_Statement.docx","Open") | Q4: GENERATED / LINKED | R4: Rev.00
A5: CNT-DE-HAM-01 | B5: IA-CNT-DE-HAM-01 | C5: Container loading | Sabitleme Tahtası ( 206×9×9 ) (Hamburg): 2 adet | D5: Container loading | Sabitleme Tahtası ( 206×9×9 ) (Hamburg): 2 pcs | E5: IA-CNT-DE-HAMBURG | F5: CONTAINER | G5: 194 | H5: 0 | I5: IA-PPWR-TF-CNT-DE-HAM-01-R00 | J5: =HYPERLINK("03_CONTAINER/CNT-DE-HAM-01/01_Technical_File.docx","Open") | K5: IA-PPWR-DOC-CNT-DE-HAM-01-R00 | L5: =HYPERLINK("03_CONTAINER/CNT-DE-HAM-01/02_EU_DoC.docx","Open") | M5: IA-PPWR-LBL-CNT-DE-HAM-01-R00 | N5: =HYPERLINK("03_CONTAINER/CNT-DE-HAM-01/03_Label.docx","Open") | O5: IA-PPWR-STM-CNT-DE-HAM-01-R00 | P5: =HYPERLINK("03_CONTAINER/CNT-DE-HAM-01/04_Shipment_Statement.docx","Open") | Q5: GENERATED / LINKED | R5: Rev.00
A6: IND-24V-01 | B6: IA-IND-24V-01 | C6: 24V | Palet (4001005): 1 adet | D6: 24V | Pallet (4001005): 1 pc | E6: IA-IND-24V | F6: INDUSTRIAL | G6: 27.388 | H6: 0 | I6: IA-PPWR-TF-IND-24V-01-R00 | J6: =HYPERLINK("02_INDUSTRIAL/IND-24V-01/01_Technical_File.docx","Open") | K6: IA-PPWR-DOC-IND-24V-01-R00 | L6: =HYPERLINK("02_INDUSTRIAL/IND-24V-01/02_EU_DoC.docx","Open") | M6: IA-PPWR-LBL-IND-24V-01-R00 | N6: =HYPERLINK("02_INDUSTRIAL/IND-24V-01/03_Label.docx","Open") | O6: IA-PPWR-STM-IND-24V-01-R00 | P6: =HYPERLINK("02_INDUSTRIAL/IND-24V-01/04_Shipment_Statement.docx","Open") | Q6: GENERATED / LINKED | R6: Rev.00
A7: IND-48V-01 | B7: IA-IND-48V-01 | C7: 48V | Palet (4001005): 1 adet | D7: 48V | Pallet (4001005): 1 pc | E7: IA-IND-48V | F7: INDUSTRIAL | G7: 27.5767 | H7: 0 | I7: IA-PPWR-TF-IND-48V-01-R00 | J7: =HYPERLINK("02_INDUSTRIAL/IND-48V-01/01_Technical_File.docx","Open") | K7: IA-PPWR-DOC-IND-48V-01-R00 | L7: =HYPERLINK("02_INDUSTRIAL/IND-48V-01/02_EU_DoC.docx","Open") | M7: IA-PPWR-LBL-IND-48V-01-R00 | N7: =HYPERLINK("02_INDUSTRIAL/IND-48V-01/03_Label.docx","Open") | O7: IA-PPWR-STM-IND-48V-01-R00 | P7: =HYPERLINK("02_INDUSTRIAL/IND-48V-01/04_Shipment_Statement.docx","Open") | Q7: GENERATED / LINKED | R7: Rev.00
A8: IND-80V-01 | B8: IA-IND-80V-01 | C8: 80V | Palet (4000973): 1 adet | D8: 80V | Pallet (4000973): 1 pc | E8: IA-IND-80V | F8: INDUSTRIAL | G8: 32.63147 | H8: 0 | I8: IA-PPWR-TF-IND-80V-01-R00 | J8: =HYPERLINK("02_INDUSTRIAL/IND-80V-01/01_Technical_File.docx","Open") | K8: IA-PPWR-DOC-IND-80V-01-R00 | L8: =HYPERLINK("02_INDUSTRIAL/IND-80V-01/02_EU_DoC.docx","Open") | M8: IA-PPWR-LBL-IND-80V-01-R00 | N8: =HYPERLINK("02_INDUSTRIAL/IND-80V-01/03_Label.docx","Open") | O8: IA-PPWR-STM-IND-80V-01-R00 | P8: =HYPERLINK("02_INDUSTRIAL/IND-80V-01/04_Shipment_Statement.docx","Open") | Q8: GENERATED / LINKED | R8: Rev.00
A9: ST-012-EUR-01 | B9: IA-ST-012-EUR-01 | C9: C | Palet (4000038): 1 adet | Köşebent (4000590): 4 adet | D9: C | Pallet (4000038): 1 pc | Edge protector (4000590): 4 pcs | E9: IA-ST-CFG-0004 | F9: STARTER | G9: 29.326 | H9: 1 | I9: IA-PPWR-TF-ST-012-EUR-01-R00 | J9: =HYPERLINK("01_STARTER/ST-012-EUR-01/01_Technical_File.docx","Open") | K9: IA-PPWR-DOC-ST-012-EUR-01-R00 | L9: =HYPERLINK("01_STARTER/ST-012-EUR-01/02_EU_DoC.docx","Open") | M9: IA-PPWR-LBL-ST-012-EUR-01-R00 | N9: =HYPERLINK("01_STARTER/ST-012-EUR-01/03_Label.docx","Open") | O9: IA-PPWR-STM-ST-012-EUR-01-R00 | P9: =HYPERLINK("01_STARTER/ST-012-EUR-01/04_Shipment_Statement.docx","Open") | Q9: GENERATED / LINKED | R9: Rev.00
A10: ST-012-EUR-02 | B10: IA-ST-012-EUR-02 | C10: L6 | Palet (4000038): 1 adet | Köşebent (4000590): 4 adet | D10: L6 | Pallet (4000038): 1 pc | Edge protector (4000590): 4 pcs | E10: IA-ST-CFG-0005 | F10: STARTER | G10: 27.526 | H10: 1 | I10: IA-PPWR-TF-ST-012-EUR-02-R00 | J10: =HYPERLINK("01_STARTER/ST-012-EUR-02/01_Technical_File.docx","Open") | K10: IA-PPWR-DOC-ST-012-EUR-02-R00 | L10: =HYPERLINK("01_STARTER/ST-012-EUR-02/02_EU_DoC.docx","Open") | M10: IA-PPWR-LBL-ST-012-EUR-02-R00 | N10: =HYPERLINK("01_STARTER/ST-012-EUR-02/03_Label.docx","Open") | O10: IA-PPWR-STM-ST-012-EUR-02-R00 | P10: =HYPERLINK("01_STARTER/ST-012-EUR-02/04_Shipment_Statement.docx","Open") | Q10: GENERATED / LINKED | R10: Rev.00
A11: ST-012-EUR-03 | B11: IA-ST-012-EUR-03 | C11: C | Palet (4000038): 1 adet | Köşebent (4000590): 2 adet | D11: C | Pallet (4000038): 1 pc | Edge protector (4000590): 2 pcs | E11: IA-ST-CFG-0006 | F11: STARTER | G11: 29.0392 | H11: 2 | I11: IA-PPWR-TF-ST-012-EUR-03-R00 | J11: =HYPERLINK("01_STARTER/ST-012-EUR-03/01_Technical_File.docx","Open") | K11: IA-PPWR-DOC-ST-012-EUR-03-R00 | L11: =HYPERLINK("01_STARTER/ST-012-EUR-03/02_EU_DoC.docx","Open") | M11: IA-PPWR-LBL-ST-012-EUR-03-R00 | N11: =HYPERLINK("01_STARTER/ST-012-EUR-03/03_Label.docx","Open") | O11: IA-PPWR-STM-ST-012-EUR-03-R00 | P11: =HYPERLINK("01_STARTER/ST-012-EUR-03/04_Shipment_Statement.docx","Open") | Q11: GENERATED / LINKED | R11: Rev.00
A12: ST-018-EUR-01 | B12: IA-ST-018-EUR-01 | C12: C | Palet (4000038): 1 adet | Köşebent (4001160): 4 adet | D12: C | Pallet (4000038): 1 pc | Edge protector (4001160): 4 pcs | E12: IA-ST-CFG-0012 | F12: STARTER | G12: 32.434 | H12: 1 | I12: IA-PPWR-TF-ST-018-EUR-01-R00 | J12: =HYPERLINK("01_STARTER/ST-018-EUR-01/01_Technical_File.docx","Open") | K12: IA-PPWR-DOC-ST-018-EUR-01-R00 | L12: =HYPERLINK("01_STARTER/ST-018-EUR-01/02_EU_DoC.docx","Open") | M12: IA-PPWR-LBL-ST-018-EUR-01-R00 | N12: =HYPERLINK("01_STARTER/ST-018-EUR-01/03_Label.docx","Open") | O12: IA-PPWR-STM-ST-018-EUR-01-R00 | P12: =HYPERLINK("01_STARTER/ST-018-EUR-01/04_Shipment_Statement.docx","Open") | Q12: GENERATED / LINKED | R12: Rev.00
A13: ST-018-EUR-02 | B13: IA-ST-018-EUR-02 | C13: C | Palet (4000038): 1 adet | Köşebent (4000590): 4 adet | D13: C | Pallet (4000038): 1 pc | Edge protector (4000590): 4 pcs | E13: IA-ST-CFG-0013 | F13: STARTER | G13: 30.194 | H13: 4 | I13: IA-PPWR-TF-ST-018-EUR-02-R00 | J13: =HYPERLINK("01_STARTER/ST-018-EUR-02/01_Technical_File.docx","Open") | K13: IA-PPWR-DOC-ST-018-EUR-02-R00 | L13: =HYPERLINK("01_STARTER/ST-018-EUR-02/02_EU_DoC.docx","Open") | M13: IA-PPWR-LBL-ST-018-EUR-02-R00 | N13: =HYPERLINK("01_STARTER/ST-018-EUR-02/03_Label.docx","Open") | O13: IA-PPWR-STM-ST-018-EUR-02-R00 | P13: =HYPERLINK("01_STARTER/ST-018-EUR-02/04_Shipment_Statement.docx","Open") | Q13: GENERATED / LINKED | R13: Rev.00
A14: ST-018-EUR-03 | B14: IA-ST-018-EUR-03 | C14: C | Palet (4000038): 1 adet | Shrink film (4000557): 1.08 kg | Köşebent (4000590): 2 adet | D14: C | Pallet (4000038): 1 pc | Shrink film (4000557): 1.08 kg | Edge protector (4000590): 2 pcs | E14: IA-ST-CFG-0014 | F14: STARTER | G14: 30.9872 | H14: 23 | I14: IA-PPWR-TF-ST-018-EUR-03-R00 | J14: =HYPERLINK("01_STARTER/ST-018-EUR-03/01_Technical_File.docx","Open") | K14: IA-PPWR-DOC-ST-018-EUR-03-R00 | L14: =HYPERLINK("01_STARTER/ST-018-EUR-03/02_EU_DoC.docx","Open") | M14: IA-PPWR-LBL-ST-018-EUR-03-R00 | N14: =HYPERLINK("01_STARTER/ST-018-EUR-03/03_Label.docx","Open") | O14: IA-PPWR-STM-ST-018-EUR-03-R00 | P14: =HYPERLINK("01_STARTER/ST-018-EUR-03/04_Shipment_Statement.docx","Open") | Q14: GENERATED / LINKED | R14: Rev.00
A15: ST-018-EUR-04 | B15: IA-ST-018-EUR-04 | C15: C | Palet (4000038): 1 adet | Honeycomb (4001186): 3 adet | D15: C | Pallet (4000038): 1 pc | Honeycomb (4001186): 3 pcs | E15: IA-ST-CFG-0015 | F15: STARTER | G15: 30.0392 | H15: 6 | I15: IA-PPWR-TF-ST-018-EUR-04-R00 | J15: =HYPERLINK("01_STARTER/ST-018-EUR-04/01_Technical_File.docx","Open") | K15: IA-PPWR-DOC-ST-018-EUR-04-R00 | L15: =HYPERLINK("01_STARTER/ST-018-EUR-04/02_EU_DoC.docx","Open") | M15: IA-PPWR-LBL-ST-018-EUR-04-R00 | N15: =HYPERLINK("01_STARTER/ST-018-EUR-04/03_Label.docx","Open") | O15: IA-PPWR-STM-ST-018-EUR-04-R00 | P15: =HYPERLINK("01_STARTER/ST-018-EUR-04/04_Shipment_Statement.docx","Open") | Q15: GENERATED / LINKED | R15: Rev.00
A16: ST-018-EUR-05 | B16: IA-ST-018-EUR-05 | C16: C | Palet (4000038): 1 adet | Çember (4000450): kullanılmaz | D16: C | Pallet (4000038): 1 pc | Strap (4000450): not used | E16: IA-ST-CFG-0016 | F16: STARTER | G16: 30.7004 | H16: 7 | I16: IA-PPWR-TF-ST-018-EUR-05-R00 | J16: =HYPERLINK("01_STARTER/ST-018-EUR-05/01_Technical_File.docx","Open") | K16: IA-PPWR-DOC-ST-018-EUR-05-R00 | L16: =HYPERLINK("01_STARTER/ST-018-EUR-05/02_EU_DoC.docx","Open") | M16: IA-PPWR-LBL-ST-018-EUR-05-R00 | N16: =HYPERLINK("01_STARTER/ST-018-EUR-05/03_Label.docx","Open") | O16: IA-PPWR-STM-ST-018-EUR-05-R00 | P16: =HYPERLINK("01_STARTER/ST-018-EUR-05/04_Shipment_Statement.docx","Open") | Q16: GENERATED / LINKED | R16: Rev.00
A17: ST-021-EUR-01 | B17: IA-ST-021-EUR-01 | C17: B | B TİPİ PVC üst kapak (4000591): 21 adet | D17: B | B TİPİ PVC upper cover (4000591): 21 pcs | E17: IA-ST-CFG-0027 | F17: STARTER | G17: 32.37481 | H17: 1 | I17: IA-PPWR-TF-ST-021-EUR-01-R00 | J17: =HYPERLINK("01_STARTER/ST-021-EUR-01/01_Technical_File.docx","Open") | K17: IA-PPWR-DOC-ST-021-EUR-01-R00 | L17: =HYPERLINK("01_STARTER/ST-021-EUR-01/02_EU_DoC.docx","Open") | M17: IA-PPWR-LBL-ST-021-EUR-01-R00 | N17: =HYPERLINK("01_STARTER/ST-021-EUR-01/03_Label.docx","Open") | O17: IA-PPWR-STM-ST-021-EUR-01-R00 | P17: =HYPERLINK("01_STARTER/ST-021-EUR-01/04_Shipment_Statement.docx","Open") | Q17: GENERATED / LINKED | R17: Rev.00
A18: ST-021-EUR-02 | B18: IA-ST-021-EUR-02 | C18: B | Palet (4000038): 1 adet | Köşebent (4000590): 4 adet | D18: B | Pallet (4000038): 1 pc | Edge protector (4000590): 4 pcs | E18: IA-ST-CFG-0028 | F18: STARTER | G18: 29.9 | H18: 3 | I18: IA-PPWR-TF-ST-021-EUR-02-R00 | J18: =HYPERLINK("01_STARTER/ST-021-EUR-02/01_Technical_File.docx","Open") | K18: IA-PPWR-DOC-ST-021-EUR-02-R00 | L18: =HYPERLINK("01_STARTER/ST-021-EUR-02/02_EU_DoC.docx","Open") | M18: IA-PPWR-LBL-ST-021-EUR-02-R00 | N18: =HYPERLINK("01_STARTER/ST-021-EUR-02/03_Label.docx","Open") | O18: IA-PPWR-STM-ST-021-EUR-02-R00 | P18: =HYPERLINK("01_STARTER/ST-021-EUR-02/04_Shipment_Statement.docx","Open") | Q18: GENERATED / LINKED | R18: Rev.00
A19: ST-021-EUR-03 | B19: IA-ST-021-EUR-03 | C19: B | Palet (4000038): 1 adet | Shrink film (4000557): 1.155 kg | EPS (4001290): 21 adet | D19: B | Pallet (4000038): 1 pc | Shrink film (4000557): 1.155 kg | EPS (4001290): 21 pcs | E19: IA-ST-CFG-0029 | F19: STARTER | G19: 30.7682 | H19: 22 | I19: IA-PPWR-TF-ST-021-EUR-03-R00 | J19: =HYPERLINK("01_STARTER/ST-021-EUR-03/01_Technical_File.docx","Open") | K19: IA-PPWR-DOC-ST-021-EUR-03-R00 | L19: =HYPERLINK("01_STARTER/ST-021-EUR-03/02_EU_DoC.docx","Open") | M19: IA-PPWR-LBL-ST-021-EUR-03-R00 | N19: =HYPERLINK("01_STARTER/ST-021-EUR-03/03_Label.docx","Open") | O19: IA-PPWR-STM-ST-021-EUR-03-R00 | P19: =HYPERLINK("01_STARTER/ST-021-EUR-03/04_Shipment_Statement.docx","Open") | Q19: GENERATED / LINKED | R19: Rev.00
A20: ST-021-EUR-04 | B20: IA-ST-021-EUR-04 | C20: B | Palet (4000038): 1 adet | Honeycomb (4001186): 3 adet | D20: B | Pallet (4000038): 1 pc | Honeycomb (4001186): 3 pcs | E20: IA-ST-CFG-0030 | F20: STARTER | G20: 30.0392 | H20: 16 | I20: IA-PPWR-TF-ST-021-EUR-04-R00 | J20: =HYPERLINK("01_STARTER/ST-021-EUR-04/01_Technical_File.docx","Open") | K20: IA-PPWR-DOC-ST-021-EUR-04-R00 | L20: =HYPERLINK("01_STARTER/ST-021-EUR-04/02_EU_DoC.docx","Open") | M20: IA-PPWR-LBL-ST-021-EUR-04-R00 | N20: =HYPERLINK("01_STARTER/ST-021-EUR-04/03_Label.docx","Open") | O20: IA-PPWR-STM-ST-021-EUR-04-R00 | P20: =HYPERLINK("01_STARTER/ST-021-EUR-04/04_Shipment_Statement.docx","Open") | Q20: GENERATED / LINKED | R20: Rev.00
A21: ST-021-EUR-05 | B21: IA-ST-021-EUR-05 | C21: B | Palet (4000038): 1 adet | Shrink film (4000557): kullanılmaz | Köşebent (4000590): 2 adet | EPS (4001290): 21 adet | D21: B | Pallet (4000038): 1 pc | Shrink film (4000557): not used | Edge protector (4000590): 2 pcs | EPS (4001290): 21 pcs | E21: IA-ST-CFG-0031 | F21: STARTER | G21: 29.6132 | H21: 1 | I21: IA-PPWR-TF-ST-021-EUR-05-R00 | J21: =HYPERLINK("01_STARTER/ST-021-EUR-05/01_Technical_File.docx","Open") | K21: IA-PPWR-DOC-ST-021-EUR-05-R00 | L21: =HYPERLINK("01_STARTER/ST-021-EUR-05/02_EU_DoC.docx","Open") | M21: IA-PPWR-LBL-ST-021-EUR-05-R00 | N21: =HYPERLINK("01_STARTER/ST-021-EUR-05/03_Label.docx","Open") | O21: IA-PPWR-STM-ST-021-EUR-05-R00 | P21: =HYPERLINK("01_STARTER/ST-021-EUR-05/04_Shipment_Statement.docx","Open") | Q21: GENERATED / LINKED | R21: Rev.00
A22: ST-021-STD-01 | B22: IA-ST-021-STD-01 | C22: C | Palet (4000037): 1 adet | Streç ped (4000301): 0.175 kg | D22: C | Pallet (4000037): 1 pc | Stretch pad (4000301): 0.175 kg | E22: IA-ST-CFG-0020 | F22: STARTER | G22: 31.8142 | H22: 1 | I22: IA-PPWR-TF-ST-021-STD-01-R00 | J22: =HYPERLINK("01_STARTER/ST-021-STD-01/01_Technical_File.docx","Open") | K22: IA-PPWR-DOC-ST-021-STD-01-R00 | L22: =HYPERLINK("01_STARTER/ST-021-STD-01/02_EU_DoC.docx","Open") | M22: IA-PPWR-LBL-ST-021-STD-01-R00 | N22: =HYPERLINK("01_STARTER/ST-021-STD-01/03_Label.docx","Open") | O22: IA-PPWR-STM-ST-021-STD-01-R00 | P22: =HYPERLINK("01_STARTER/ST-021-STD-01/04_Shipment_Statement.docx","Open") | Q22: GENERATED / LINKED | R22: Rev.00
A23: ST-021-STD-02 | B23: IA-ST-021-STD-02 | C23: C | Palet (4000037): 1 adet | Köşebent (4000590): 4 adet | D23: C | Pallet (4000037): 1 pc | Edge protector (4000590): 4 pcs | E23: IA-ST-CFG-0021 | F23: STARTER | G23: 32.112 | H23: 1 | I23: IA-PPWR-TF-ST-021-STD-02-R00 | J23: =HYPERLINK("01_STARTER/ST-021-STD-02/01_Technical_File.docx","Open") | K23: IA-PPWR-DOC-ST-021-STD-02-R00 | L23: =HYPERLINK("01_STARTER/ST-021-STD-02/02_EU_DoC.docx","Open") | M23: IA-PPWR-LBL-ST-021-STD-02-R00 | N23: =HYPERLINK("01_STARTER/ST-021-STD-02/03_Label.docx","Open") | O23: IA-PPWR-STM-ST-021-STD-02-R00 | P23: =HYPERLINK("01_STARTER/ST-021-STD-02/04_Shipment_Statement.docx","Open") | Q23: GENERATED / LINKED | R23: Rev.00
A24: ST-021-STD-03 | B24: IA-ST-021-STD-03 | C24: C | Palet (4000037): 1 adet | Streç ped (4000301): 0.186 kg | Köşebent (4000590): 2 adet | D24: C | Pallet (4000037): 1 pc | Stretch pad (4000301): 0.186 kg | Edge protector (4000590): 2 pcs | E24: IA-ST-CFG-0023 | F24: STARTER | G24: 31.8252 | H24: 52 | I24: IA-PPWR-TF-ST-021-STD-03-R00 | J24: =HYPERLINK("01_STARTER/ST-021-STD-03/01_Technical_File.docx","Open") | K24: IA-PPWR-DOC-ST-021-STD-03-R00 | L24: =HYPERLINK("01_STARTER/ST-021-STD-03/02_EU_DoC.docx","Open") | M24: IA-PPWR-LBL-ST-021-STD-03-R00 | N24: =HYPERLINK("01_STARTER/ST-021-STD-03/03_Label.docx","Open") | O24: IA-PPWR-STM-ST-021-STD-03-R00 | P24: =HYPERLINK("01_STARTER/ST-021-STD-03/04_Shipment_Statement.docx","Open") | Q24: GENERATED / LINKED | R24: Rev.00
A25: ST-021-STD-04 | B25: IA-ST-021-STD-04 | C25: C | Palet (4000037): 1 adet | Çember (4000450): kullanılmaz | D25: C | Pallet (4000037): 1 pc | Strap (4000450): not used | E25: IA-ST-CFG-0024 | F25: STARTER | G25: 31.5384 | H25: 24 | I25: IA-PPWR-TF-ST-021-STD-04-R00 | J25: =HYPERLINK("01_STARTER/ST-021-STD-04/01_Technical_File.docx","Open") | K25: IA-PPWR-DOC-ST-021-STD-04-R00 | L25: =HYPERLINK("01_STARTER/ST-021-STD-04/02_EU_DoC.docx","Open") | M25: IA-PPWR-LBL-ST-021-STD-04-R00 | N25: =HYPERLINK("01_STARTER/ST-021-STD-04/03_Label.docx","Open") | O25: IA-PPWR-STM-ST-021-STD-04-R00 | P25: =HYPERLINK("01_STARTER/ST-021-STD-04/04_Shipment_Statement.docx","Open") | Q25: GENERATED / LINKED | R25: Rev.00
A26: ST-021-STD-05 | B26: IA-ST-021-STD-05 | C26: C | Palet (4000037): 1 adet | Shrink film (4001177): 0.597 kg | D26: C | Pallet (4000037): 1 pc | Shrink film (4001177): 0.597 kg | E26: IA-ST-CFG-0025 | F26: STARTER | G26: 30.983 | H26: 1 | I26: IA-PPWR-TF-ST-021-STD-05-R00 | J26: =HYPERLINK("01_STARTER/ST-021-STD-05/01_Technical_File.docx","Open") | K26: IA-PPWR-DOC-ST-021-STD-05-R00 | L26: =HYPERLINK("01_STARTER/ST-021-STD-05/02_EU_DoC.docx","Open") | M26: IA-PPWR-LBL-ST-021-STD-05-R00 | N26: =HYPERLINK("01_STARTER/ST-021-STD-05/03_Label.docx","Open") | O26: IA-PPWR-STM-ST-021-STD-05-R00 | P26: =HYPERLINK("01_STARTER/ST-021-STD-05/04_Shipment_Statement.docx","Open") | Q26: GENERATED / LINKED | R26: Rev.00
A27: ST-024-EUR-01 | B27: IA-ST-024-EUR-01 | C27: TRACTOR | Palet (4000038): 1 adet | Honeycomb (4001186): 2 adet | D27: TRACTOR | Pallet (4000038): 1 pc | Honeycomb (4001186): 2 pcs | E27: IA-ST-CFG-0035 | F27: STARTER | G27: 36.726 | H27: 1 | I27: IA-PPWR-TF-ST-024-EUR-01-R00 | J27: =HYPERLINK("01_STARTER/ST-024-EUR-01/01_Technical_File.docx","Open") | K27: IA-PPWR-DOC-ST-024-EUR-01-R00 | L27: =HYPERLINK("01_STARTER/ST-024-EUR-01/02_EU_DoC.docx","Open") | M27: IA-PPWR-LBL-ST-024-EUR-01-R00 | N27: =HYPERLINK("01_STARTER/ST-024-EUR-01/03_Label.docx","Open") | O27: IA-PPWR-STM-ST-024-EUR-01-R00 | P27: =HYPERLINK("01_STARTER/ST-024-EUR-01/04_Shipment_Statement.docx","Open") | Q27: GENERATED / LINKED | R27: Rev.00
A28: ST-024-EUR-02 | B28: IA-ST-024-EUR-02 | C28: A | A TİPİ VAKUM PVC PVC üst kapak (4000720): 24 adet | D28: A | A TİPİ VAKUM PVC PVC upper cover (4000720): 24 pcs | E28: IA-ST-CFG-0037 | F28: STARTER | G28: 32.84464 | H28: 1 | I28: IA-PPWR-TF-ST-024-EUR-02-R00 | J28: =HYPERLINK("01_STARTER/ST-024-EUR-02/01_Technical_File.docx","Open") | K28: IA-PPWR-DOC-ST-024-EUR-02-R00 | L28: =HYPERLINK("01_STARTER/ST-024-EUR-02/02_EU_DoC.docx","Open") | M28: IA-PPWR-LBL-ST-024-EUR-02-R00 | N28: =HYPERLINK("01_STARTER/ST-024-EUR-02/03_Label.docx","Open") | O28: IA-PPWR-STM-ST-024-EUR-02-R00 | P28: =HYPERLINK("01_STARTER/ST-024-EUR-02/04_Shipment_Statement.docx","Open") | Q28: GENERATED / LINKED | R28: Rev.00
A29: ST-024-EUR-03 | B29: IA-ST-024-EUR-03 | C29: A | Palet (4000038): 1 adet | Köşebent (4000590): 4 adet | D29: A | Pallet (4000038): 1 pc | Edge protector (4000590): 4 pcs | E29: IA-ST-CFG-0038 | F29: STARTER | G29: 29.63 | H29: 2 | I29: IA-PPWR-TF-ST-024-EUR-03-R00 | J29: =HYPERLINK("01_STARTER/ST-024-EUR-03/01_Technical_File.docx","Open") | K29: IA-PPWR-DOC-ST-024-EUR-03-R00 | L29: =HYPERLINK("01_STARTER/ST-024-EUR-03/02_EU_DoC.docx","Open") | M29: IA-PPWR-LBL-ST-024-EUR-03-R00 | N29: =HYPERLINK("01_STARTER/ST-024-EUR-03/03_Label.docx","Open") | O29: IA-PPWR-STM-ST-024-EUR-03-R00 | P29: =HYPERLINK("01_STARTER/ST-024-EUR-03/04_Shipment_Statement.docx","Open") | Q29: GENERATED / LINKED | R29: Rev.00
A30: ST-024-EUR-04 | B30: IA-ST-024-EUR-04 | C30: A | Palet (4000038): 1 adet | Köşebent (4000590): 2 adet | D30: A | Pallet (4000038): 1 pc | Edge protector (4000590): 2 pcs | E30: IA-ST-CFG-0039 | F30: STARTER | G30: 30.6632 | H30: 18 | I30: IA-PPWR-TF-ST-024-EUR-04-R00 | J30: =HYPERLINK("01_STARTER/ST-024-EUR-04/01_Technical_File.docx","Open") | K30: IA-PPWR-DOC-ST-024-EUR-04-R00 | L30: =HYPERLINK("01_STARTER/ST-024-EUR-04/02_EU_DoC.docx","Open") | M30: IA-PPWR-LBL-ST-024-EUR-04-R00 | N30: =HYPERLINK("01_STARTER/ST-024-EUR-04/03_Label.docx","Open") | O30: IA-PPWR-STM-ST-024-EUR-04-R00 | P30: =HYPERLINK("01_STARTER/ST-024-EUR-04/04_Shipment_Statement.docx","Open") | Q30: GENERATED / LINKED | R30: Rev.00
A31: ST-024-STD-01 | B31: IA-ST-024-STD-01 | C31: C | Palet (4000037): 1 adet | EPS (4001281): 24 adet | D31: C | Pallet (4000037): 1 pc | EPS (4001281): 24 pcs | E31: IA-ST-CFG-0034 | F31: STARTER | G31: 31.23 | H31: 1 | I31: IA-PPWR-TF-ST-024-STD-01-R00 | J31: =HYPERLINK("01_STARTER/ST-024-STD-01/01_Technical_File.docx","Open") | K31: IA-PPWR-DOC-ST-024-STD-01-R00 | L31: =HYPERLINK("01_STARTER/ST-024-STD-01/02_EU_DoC.docx","Open") | M31: IA-PPWR-LBL-ST-024-STD-01-R00 | N31: =HYPERLINK("01_STARTER/ST-024-STD-01/03_Label.docx","Open") | O31: IA-PPWR-STM-ST-024-STD-01-R00 | P31: =HYPERLINK("01_STARTER/ST-024-STD-01/04_Shipment_Statement.docx","Open") | Q31: GENERATED / LINKED | R31: Rev.00
A32: ST-027-STD90-01 | B32: IA-ST-027-STD90-01 | C32: TANK | TANK PVC üst kapak (4000493): 27 adet | Çember (4000450): 7 m | D32: TANK | TANK PVC upper cover (4000493): 27 pcs | Strap (4000450): 7 m | E32: IA-ST-CFG-0043 | F32: STARTER | G32: 25.58996 | H32: 1 | I32: IA-PPWR-TF-ST-027-STD90-01-R00 | J32: =HYPERLINK("01_STARTER/ST-027-STD90-01/01_Technical_File.docx","Open") | K32: IA-PPWR-DOC-ST-027-STD90-01-R00 | L32: =HYPERLINK("01_STARTER/ST-027-STD90-01/02_EU_DoC.docx","Open") | M32: IA-PPWR-LBL-ST-027-STD90-01-R00 | N32: =HYPERLINK("01_STARTER/ST-027-STD90-01/03_Label.docx","Open") | O32: IA-PPWR-STM-ST-027-STD90-01-R00 | P32: =HYPERLINK("01_STARTER/ST-027-STD90-01/04_Shipment_Statement.docx","Open") | Q32: GENERATED / LINKED | R32: Rev.00
A33: ST-027-STD90-02 | B33: IA-ST-027-STD90-02 | C33: TANK | TANK PVC üst kapak (4000493): 27 adet | Çember (4000450): kullanılmaz | D33: TANK | TANK PVC upper cover (4000493): 27 pcs | Strap (4000450): not used | E33: IA-ST-CFG-0044 | F33: STARTER | G33: 25.50316 | H33: 1 | I33: IA-PPWR-TF-ST-027-STD90-02-R00 | J33: =HYPERLINK("01_STARTER/ST-027-STD90-02/01_Technical_File.docx","Open") | K33: IA-PPWR-DOC-ST-027-STD90-02-R00 | L33: =HYPERLINK("01_STARTER/ST-027-STD90-02/02_EU_DoC.docx","Open") | M33: IA-PPWR-LBL-ST-027-STD90-02-R00 | N33: =HYPERLINK("01_STARTER/ST-027-STD90-02/03_Label.docx","Open") | O33: IA-PPWR-STM-ST-027-STD90-02-R00 | P33: =HYPERLINK("01_STARTER/ST-027-STD90-02/04_Shipment_Statement.docx","Open") | Q33: GENERATED / LINKED | R33: Rev.00
A34: ST-028-STD-01 | B34: IA-ST-028-STD-01 | C34: L6 | Palet (4000037): 1 adet | Shrink film (4000608): 1.12 kg | D34: L6 | Pallet (4000037): 1 pc | Shrink film (4000608): 1.12 kg | E34: IA-ST-CFG-0045 | F34: STARTER | G34: 29.056 | H34: 1 | I34: IA-PPWR-TF-ST-028-STD-01-R00 | J34: =HYPERLINK("01_STARTER/ST-028-STD-01/01_Technical_File.docx","Open") | K34: IA-PPWR-DOC-ST-028-STD-01-R00 | L34: =HYPERLINK("01_STARTER/ST-028-STD-01/02_EU_DoC.docx","Open") | M34: IA-PPWR-LBL-ST-028-STD-01-R00 | N34: =HYPERLINK("01_STARTER/ST-028-STD-01/03_Label.docx","Open") | O34: IA-PPWR-STM-ST-028-STD-01-R00 | P34: =HYPERLINK("01_STARTER/ST-028-STD-01/04_Shipment_Statement.docx","Open") | Q34: GENERATED / LINKED | R34: Rev.00
A35: ST-030-STD-01 | B35: IA-ST-030-STD-01 | C35: L5 | Palet (4000037): 1 adet | Shrink film (4000608): 1.2 kg | D35: L5 | Pallet (4000037): 1 pc | Shrink film (4000608): 1.2 kg | E35: IA-ST-CFG-0046 | F35: STARTER | G35: 29.136 | H35: 1 | I35: IA-PPWR-TF-ST-030-STD-01-R00 | J35: =HYPERLINK("01_STARTER/ST-030-STD-01/01_Technical_File.docx","Open") | K35: IA-PPWR-DOC-ST-030-STD-01-R00 | L35: =HYPERLINK("01_STARTER/ST-030-STD-01/02_EU_DoC.docx","Open") | M35: IA-PPWR-LBL-ST-030-STD-01-R00 | N35: =HYPERLINK("01_STARTER/ST-030-STD-01/03_Label.docx","Open") | O35: IA-PPWR-STM-ST-030-STD-01-R00 | P35: =HYPERLINK("01_STARTER/ST-030-STD-01/04_Shipment_Statement.docx","Open") | Q35: GENERATED / LINKED | R35: Rev.00
A36: ST-030-STD-02 | B36: IA-ST-030-STD-02 | C36: A | Palet (4000037): 1 adet | Shrink film (4000557): 1.65 kg | Köşebent (4000590): 4 adet | D36: A | Pallet (4000037): 1 pc | Shrink film (4000557): 1.65 kg | Edge protector (4000590): 4 pcs | E36: IA-ST-CFG-0047 | F36: STARTER | G36: 31.986 | H36: 2 | I36: IA-PPWR-TF-ST-030-STD-02-R00 | J36: =HYPERLINK("01_STARTER/ST-030-STD-02/01_Technical_File.docx","Open") | K36: IA-PPWR-DOC-ST-030-STD-02-R00 | L36: =HYPERLINK("01_STARTER/ST-030-STD-02/02_EU_DoC.docx","Open") | M36: IA-PPWR-LBL-ST-030-STD-02-R00 | N36: =HYPERLINK("01_STARTER/ST-030-STD-02/03_Label.docx","Open") | O36: IA-PPWR-STM-ST-030-STD-02-R00 | P36: =HYPERLINK("01_STARTER/ST-030-STD-02/04_Shipment_Statement.docx","Open") | Q36: GENERATED / LINKED | R36: Rev.00
A37: ST-030-STD-03 | B37: IA-ST-030-STD-03 | C37: B | Palet (4000037): 1 adet | Shrink film (4000557): 1.65 kg | Köşebent (4000590): 4 adet | D37: B | Pallet (4000037): 1 pc | Shrink film (4000557): 1.65 kg | Edge protector (4000590): 4 pcs | E37: IA-ST-CFG-0048 | F37: STARTER | G37: 32.676 | H37: 2 | I37: IA-PPWR-TF-ST-030-STD-03-R00 | J37: =HYPERLINK("01_STARTER/ST-030-STD-03/01_Technical_File.docx","Open") | K37: IA-PPWR-DOC-ST-030-STD-03-R00 | L37: =HYPERLINK("01_STARTER/ST-030-STD-03/02_EU_DoC.docx","Open") | M37: IA-PPWR-LBL-ST-030-STD-03-R00 | N37: =HYPERLINK("01_STARTER/ST-030-STD-03/03_Label.docx","Open") | O37: IA-PPWR-STM-ST-030-STD-03-R00 | P37: =HYPERLINK("01_STARTER/ST-030-STD-03/04_Shipment_Statement.docx","Open") | Q37: GENERATED / LINKED | R37: Rev.00
A38: ST-030-STD-04 | B38: IA-ST-030-STD-04 | C38: A | Palet (4000037): 1 adet | Shrink film (4000557): kullanılmaz | Köşebent (4000590): 4 adet | D38: A | Pallet (4000037): 1 pc | Shrink film (4000557): not used | Edge protector (4000590): 4 pcs | E38: IA-ST-CFG-0049 | F38: STARTER | G38: 30.336 | H38: 2 | I38: IA-PPWR-TF-ST-030-STD-04-R00 | J38: =HYPERLINK("01_STARTER/ST-030-STD-04/01_Technical_File.docx","Open") | K38: IA-PPWR-DOC-ST-030-STD-04-R00 | L38: =HYPERLINK("01_STARTER/ST-030-STD-04/02_EU_DoC.docx","Open") | M38: IA-PPWR-LBL-ST-030-STD-04-R00 | N38: =HYPERLINK("01_STARTER/ST-030-STD-04/03_Label.docx","Open") | O38: IA-PPWR-STM-ST-030-STD-04-R00 | P38: =HYPERLINK("01_STARTER/ST-030-STD-04/04_Shipment_Statement.docx","Open") | Q38: GENERATED / LINKED | R38: Rev.00
A39: ST-030-STD-05 | B39: IA-ST-030-STD-05 | C39: A | Palet (4000037): 1 adet | Köşebent (4000590): 2 adet | D39: A | Pallet (4000037): 1 pc | Edge protector (4000590): 2 pcs | E39: IA-ST-CFG-0051 | F39: STARTER | G39: 31.6992 | H39: 34 | I39: IA-PPWR-TF-ST-030-STD-05-R00 | J39: =HYPERLINK("01_STARTER/ST-030-STD-05/01_Technical_File.docx","Open") | K39: IA-PPWR-DOC-ST-030-STD-05-R00 | L39: =HYPERLINK("01_STARTER/ST-030-STD-05/02_EU_DoC.docx","Open") | M39: IA-PPWR-LBL-ST-030-STD-05-R00 | N39: =HYPERLINK("01_STARTER/ST-030-STD-05/03_Label.docx","Open") | O39: IA-PPWR-STM-ST-030-STD-05-R00 | P39: =HYPERLINK("01_STARTER/ST-030-STD-05/04_Shipment_Statement.docx","Open") | Q39: GENERATED / LINKED | R39: Rev.00
A40: ST-030-STD-06 | B40: IA-ST-030-STD-06 | C40: B | Palet (4000037): 1 adet | Köşebent (4000590): 2 adet | D40: B | Pallet (4000037): 1 pc | Edge protector (4000590): 2 pcs | E40: IA-ST-CFG-0052 | F40: STARTER | G40: 32.3892 | H40: 59 | I40: IA-PPWR-TF-ST-030-STD-06-R00 | J40: =HYPERLINK("01_STARTER/ST-030-STD-06/01_Technical_File.docx","Open") | K40: IA-PPWR-DOC-ST-030-STD-06-R00 | L40: =HYPERLINK("01_STARTER/ST-030-STD-06/02_EU_DoC.docx","Open") | M40: IA-PPWR-LBL-ST-030-STD-06-R00 | N40: =HYPERLINK("01_STARTER/ST-030-STD-06/03_Label.docx","Open") | O40: IA-PPWR-STM-ST-030-STD-06-R00 | P40: =HYPERLINK("01_STARTER/ST-030-STD-06/04_Shipment_Statement.docx","Open") | Q40: GENERATED / LINKED | R40: Rev.00
...

Sheet TECHNICAL_FILES
A1: Technical File Code | B1: Packaging Set Code | C1: Configuration ID | D1: Variant Basis | E1: Source BOM | F1: Product Count | G1: BOM Line Count | H1: Packaging Tare | I1: Article 5 Assessment Basis | J1: Drawing Status | K1: Photo Status | L1: Revision | M1: Open Technical File
A2: IA-PPWR-TF-CNT-20-EUR-01-R00 | B2: CNT-20-EUR-01 | C2: IA-CNT-20-EUR-01 | D2: Container loading | OSB (5501806): 11 adet | Separatör (4000130): 10 adet | E2: IA-CNT-20-EUR | F2: 0 | G2: 8 | H2: 83.06 | I2: REV00 CURRENT EVIDENCE BASIS — ARTICLE 5 ASSESSMENT BASIS | J2: PENDING - DRAWING | K2: PENDING - PHOTOGRAPHS | L2: Rev.00 | M2: =HYPERLINK("03_CONTAINER/CNT-20-EUR-01/01_Technical_File.docx","Open")
A3: IA-PPWR-TF-CNT-20-STD-01-R00 | B3: CNT-20-STD-01 | C3: IA-CNT-20-STD-01 | D3: Container loading | OSB (5501805): 10 adet | Separatör (4000130): 10 adet | E3: IA-CNT-20-STD | F3: 0 | G3: 8 | H3: 78.06 | I3: REV00 CURRENT EVIDENCE BASIS — ARTICLE 5 ASSESSMENT BASIS | J3: PENDING - DRAWING | K3: PENDING - PHOTOGRAPHS | L3: Rev.00 | M3: =HYPERLINK("03_CONTAINER/CNT-20-STD-01/01_Technical_File.docx","Open")
A4: IA-PPWR-TF-CNT-40-IND-01-R00 | B4: CNT-40-IND-01 | C4: IA-CNT-40-IND-01 | D4: Container loading | Hava yastığı (5500759): 26 adet | Bağlama halatı (5500762): 12 m | E4: IA-CNT-40-IND | F4: 0 | G4: 5 | H4: 12.76 | I4: REV00 CURRENT EVIDENCE BASIS — ARTICLE 5 ASSESSMENT BASIS | J4: PENDING - DRAWING | K4: PENDING - PHOTOGRAPHS | L4: Rev.00 | M4: =HYPERLINK("03_CONTAINER/CNT-40-IND-01/01_Technical_File.docx","Open")
A5: IA-PPWR-TF-CNT-DE-HAM-01-R00 | B5: CNT-DE-HAM-01 | C5: IA-CNT-DE-HAM-01 | D5: Container loading | Sabitleme Tahtası ( 206×9×9 ) (Hamburg): 2 adet | E5: IA-CNT-DE-HAMBURG | F5: 0 | G5: 3 | H5: 194 | I5: REV00 CURRENT EVIDENCE BASIS — ARTICLE 5 ASSESSMENT BASIS | J5: PENDING - DRAWING | K5: PENDING - PHOTOGRAPHS | L5: Rev.00 | M5: =HYPERLINK("03_CONTAINER/CNT-DE-HAM-01/01_Technical_File.docx","Open")
A6: IA-PPWR-TF-IND-24V-01-R00 | B6: IND-24V-01 | C6: IA-IND-24V-01 | D6: 24V | Palet (4001005): 1 adet | E6: IA-IND-24V | F6: 0 | G6: 6 | H6: 27.388 | I6: REV00 CURRENT EVIDENCE BASIS — ARTICLE 5 ASSESSMENT BASIS | J6: PENDING - DRAWING | K6: PENDING - PHOTOGRAPHS | L6: Rev.00 | M6: =HYPERLINK("02_INDUSTRIAL/IND-24V-01/01_Technical_File.docx","Open")
A7: IA-PPWR-TF-IND-48V-01-R00 | B7: IND-48V-01 | C7: IA-IND-48V-01 | D7: 48V | Palet (4001005): 1 adet | E7: IA-IND-48V | F7: 0 | G7: 6 | H7: 27.5767 | I7: REV00 CURRENT EVIDENCE BASIS — ARTICLE 5 ASSESSMENT BASIS | J7: PENDING - DRAWING | K7: PENDING - PHOTOGRAPHS | L7: Rev.00 | M7: =HYPERLINK("02_INDUSTRIAL/IND-48V-01/01_Technical_File.docx","Open")
A8: IA-PPWR-TF-IND-80V-01-R00 | B8: IND-80V-01 | C8: IA-IND-80V-01 | D8: 80V | Palet (4000973): 1 adet | E8: IA-IND-80V | F8: 0 | G8: 6 | H8: 32.63147 | I8: REV00 CURRENT EVIDENCE BASIS — ARTICLE 5 ASSESSMENT BASIS | J8: PENDING - DRAWING | K8: PENDING - PHOTOGRAPHS | L8: Rev.00 | M8: =HYPERLINK("02_INDUSTRIAL/IND-80V-01/01_Technical_File.docx","Open")
A9: IA-PPWR-TF-ST-012-EUR-01-R00 | B9: ST-012-EUR-01 | C9: IA-ST-012-EUR-01 | D9: C | Palet (4000038): 1 adet | Köşebent (4000590): 4 adet | E9: IA-ST-CFG-0004 | F9: 1 | G9: 7 | H9: 29.326 | I9: REV00 CURRENT EVIDENCE BASIS — ARTICLE 5 ASSESSMENT BASIS | J9: PENDING - DRAWING | K9: PENDING - PHOTOGRAPHS | L9: Rev.00 | M9: =HYPERLINK("01_STARTER/ST-012-EUR-01/01_Technical_File.docx","Open")
A10: IA-PPWR-TF-ST-012-EUR-02-R00 | B10: ST-012-EUR-02 | C10: IA-ST-012-EUR-02 | D10: L6 | Palet (4000038): 1 adet | Köşebent (4000590): 4 adet | E10: IA-ST-CFG-0005 | F10: 1 | G10: 6 | H10: 27.526 | I10: REV00 CURRENT EVIDENCE BASIS — ARTICLE 5 ASSESSMENT BASIS | J10: PENDING - DRAWING | K10: PENDING - PHOTOGRAPHS | L10: Rev.00 | M10: =HYPERLINK("01_STARTER/ST-012-EUR-02/01_Technical_File.docx","Open")
A11: IA-PPWR-TF-ST-012-EUR-03-R00 | B11: ST-012-EUR-03 | C11: IA-ST-012-EUR-03 | D11: C | Palet (4000038): 1 adet | Köşebent (4000590): 2 adet | E11: IA-ST-CFG-0006 | F11: 2 | G11: 7 | H11: 29.0392 | I11: REV00 CURRENT EVIDENCE BASIS — ARTICLE 5 ASSESSMENT BASIS | J11: PENDING - DRAWING | K11: PENDING - PHOTOGRAPHS | L11: Rev.00 | M11: =HYPERLINK("01_STARTER/ST-012-EUR-03/01_Technical_File.docx","Open")
A12: IA-PPWR-TF-ST-018-EUR-01-R00 | B12: ST-018-EUR-01 | C12: IA-ST-018-EUR-01 | D12: C | Palet (4000038): 1 adet | Köşebent (4001160): 4 adet | E12: IA-ST-CFG-0012 | F12: 1 | G12: 9 | H12: 32.434 | I12: REV00 CURRENT EVIDENCE BASIS — ARTICLE 5 ASSESSMENT BASIS | J12: PENDING - DRAWING | K12: PENDING - PHOTOGRAPHS | L12: Rev.00 | M12: =HYPERLINK("01_STARTER/ST-018-EUR-01/01_Technical_File.docx","Open")
A13: IA-PPWR-TF-ST-018-EUR-02-R00 | B13: ST-018-EUR-02 | C13: IA-ST-018-EUR-02 | D13: C | Palet (4000038): 1 adet | Köşebent (4000590): 4 adet | E13: IA-ST-CFG-0013 | F13: 4 | G13: 7 | H13: 30.194 | I13: REV00 CURRENT EVIDENCE BASIS — ARTICLE 5 ASSESSMENT BASIS | J13: PENDING - DRAWING | K13: PENDING - PHOTOGRAPHS | L13: Rev.00 | M13: =HYPERLINK("01_STARTER/ST-018-EUR-02/01_Technical_File.docx","Open")
A14: IA-PPWR-TF-ST-018-EUR-03-R00 | B14: ST-018-EUR-03 | C14: IA-ST-018-EUR-03 | D14: C | Palet (4000038): 1 adet | Shrink film (4000557): 1.08 kg | Köşebent (4000590): 2 adet | E14: IA-ST-CFG-0014 | F14: 23 | G14: 8 | H14: 30.9872 | I14: REV00 CURRENT EVIDENCE BASIS — ARTICLE 5 ASSESSMENT BASIS | J14: PENDING - DRAWING | K14: PENDING - PHOTOGRAPHS | L14: Rev.00 | M14: =HYPERLINK("01_STARTER/ST-018-EUR-03/01_Technical_File.docx","Open")
A15: IA-PPWR-TF-ST-018-EUR-04-R00 | B15: ST-018-EUR-04 | C15: IA-ST-018-EUR-04 | D15: C | Palet (4000038): 1 adet | Honeycomb (4001186): 3 adet | E15: IA-ST-CFG-0015 | F15: 6 | G15: 7 | H15: 30.0392 | I15: REV00 CURRENT EVIDENCE BASIS — ARTICLE 5 ASSESSMENT BASIS | J15: PENDING - DRAWING | K15: PENDING - PHOTOGRAPHS | L15: Rev.00 | M15: =HYPERLINK("01_STARTER/ST-018-EUR-04/01_Technical_File.docx","Open")
A16: IA-PPWR-TF-ST-018-EUR-05-R00 | B16: ST-018-EUR-05 | C16: IA-ST-018-EUR-05 | D16: C | Palet (4000038): 1 adet | Çember (4000450): kullanılmaz | E16: IA-ST-CFG-0016 | F16: 7 | G16: 6 | H16: 30.7004 | I16: REV00 CURRENT EVIDENCE BASIS — ARTICLE 5 ASSESSMENT BASIS | J16: PENDING - DRAWING | K16: PENDING - PHOTOGRAPHS | L16: Rev.00 | M16: =HYPERLINK("01_STARTER/ST-018-EUR-05/01_Technical_File.docx","Open")
A17: IA-PPWR-TF-ST-021-EUR-01-R00 | B17: ST-021-EUR-01 | C17: IA-ST-021-EUR-01 | D17: B | B TİPİ PVC üst kapak (4000591): 21 adet | E17: IA-ST-CFG-0027 | F17: 1 | G17: 9 | H17: 32.37481 | I17: REV00 CURRENT EVIDENCE BASIS — ARTICLE 5 ASSESSMENT BASIS | J17: PENDING - DRAWING | K17: PENDING - PHOTOGRAPHS | L17: Rev.00 | M17: =HYPERLINK("01_STARTER/ST-021-EUR-01/01_Technical_File.docx","Open")
A18: IA-PPWR-TF-ST-021-EUR-02-R00 | B18: ST-021-EUR-02 | C18: IA-ST-021-EUR-02 | D18: B | Palet (4000038): 1 adet | Köşebent (4000590): 4 adet | E18: IA-ST-CFG-0028 | F18: 3 | G18: 7 | H18: 29.9 | I18: REV00 CURRENT EVIDENCE BASIS — ARTICLE 5 ASSESSMENT BASIS | J18: PENDING - DRAWING | K18: PENDING - PHOTOGRAPHS | L18: Rev.00 | M18: =HYPERLINK("01_STARTER/ST-021-EUR-02/01_Technical_File.docx","Open")
A19: IA-PPWR-TF-ST-021-EUR-03-R00 | B19: ST-021-EUR-03 | C19: IA-ST-021-EUR-03 | D19: B | Palet (4000038): 1 adet | Shrink film (4000557): 1.155 kg | EPS (4001290): 21 adet | E19: IA-ST-CFG-0029 | F19: 22 | G19: 8 | H19: 30.7682 | I19: REV00 CURRENT EVIDENCE BASIS — ARTICLE 5 ASSESSMENT BASIS | J19: PENDING - DRAWING | K19: PENDING - PHOTOGRAPHS | L19: Rev.00 | M19: =HYPERLINK("01_STARTER/ST-021-EUR-03/01_Technical_File.docx","Open")
A20: IA-PPWR-TF-ST-021-EUR-04-R00 | B20: ST-021-EUR-04 | C20: IA-ST-021-EUR-04 | D20: B | Palet (4000038): 1 adet | Honeycomb (4001186): 3 adet | E20: IA-ST-CFG-0030 | F20: 16 | G20: 7 | H20: 30.0392 | I20: REV00 CURRENT EVIDENCE BASIS — ARTICLE 5 ASSESSMENT BASIS | J20: PENDING - DRAWING | K20: PENDING - PHOTOGRAPHS | L20: Rev.00 | M20: =HYPERLINK("01_STARTER/ST-021-EUR-04/01_Technical_File.docx","Open")
A21: IA-PPWR-TF-ST-021-EUR-05-R00 | B21: ST-021-EUR-05 | C21: IA-ST-021-EUR-05 | D21: B | Palet (4000038): 1 adet | Shrink film (4000557): kullanılmaz | Köşebent (4000590): 2 adet | EPS (4001290): 21 adet | E21: IA-ST-CFG-0031 | F21: 1 | G21: 7 | H21: 29.6132 | I21: REV00 CURRENT EVIDENCE BASIS — ARTICLE 5 ASSESSMENT BASIS | J21: PENDING - DRAWING | K21: PENDING - PHOTOGRAPHS | L21: Rev.00 | M21: =HYPERLINK("01_STARTER/ST-021-EUR-05/01_Technical_File.docx","Open")
A22: IA-PPWR-TF-ST-021-STD-01-R00 | B22: ST-021-STD-01 | C22: IA-ST-021-STD-01 | D22: C | Palet (4000037): 1 adet | Streç ped (4000301): 0.175 kg | E22: IA-ST-CFG-0020 | F22: 1 | G22: 8 | H22: 31.8142 | I22: REV00 CURRENT EVIDENCE BASIS — ARTICLE 5 ASSESSMENT BASIS | J22: PENDING - DRAWING | K22: PENDING - PHOTOGRAPHS | L22: Rev.00 | M22: =HYPERLINK("01_STARTER/ST-021-STD-01/01_Technical_File.docx","Open")
A23: IA-PPWR-TF-ST-021-STD-02-R00 | B23: ST-021-STD-02 | C23: IA-ST-021-STD-02 | D23: C | Palet (4000037): 1 adet | Köşebent (4000590): 4 adet | E23: IA-ST-CFG-0021 | F23: 1 | G23: 8 | H23: 32.112 | I23: REV00 CURRENT EVIDENCE BASIS — ARTICLE 5 ASSESSMENT BASIS | J23: PENDING - DRAWING | K23: PENDING - PHOTOGRAPHS | L23: Rev.00 | M23: =HYPERLINK("01_STARTER/ST-021-STD-02/01_Technical_File.docx","Open")
A24: IA-PPWR-TF-ST-021-STD-03-R00 | B24: ST-021-STD-03 | C24: IA-ST-021-STD-03 | D24: C | Palet (4000037): 1 adet | Streç ped (4000301): 0.186 kg | Köşebent (4000590): 2 adet | E24: IA-ST-CFG-0023 | F24: 52 | G24: 8 | H24: 31.8252 | I24: REV00 CURRENT EVIDENCE BASIS — ARTICLE 5 ASSESSMENT BASIS | J24: PENDING - DRAWING | K24: PENDING - PHOTOGRAPHS | L24: Rev.00 | M24: =HYPERLINK("01_STARTER/ST-021-STD-03/01_Technical_File.docx","Open")
A25: IA-PPWR-TF-ST-021-STD-04-R00 | B25: ST-021-STD-04 | C25: IA-ST-021-STD-04 | D25: C | Palet (4000037): 1 adet | Çember (4000450): kullanılmaz | E25: IA-ST-CFG-0024 | F25: 24 | G25: 6 | H25: 31.5384 | I25: REV00 CURRENT EVIDENCE BASIS — ARTICLE 5 ASSESSMENT BASIS | J25: PENDING - DRAWING | K25: PENDING - PHOTOGRAPHS | L25: Rev.00 | M25: =HYPERLINK("01_STARTER/ST-021-STD-04/01_Technical_File.docx","Open")
A26: IA-PPWR-TF-ST-021-STD-05-R00 | B26: ST-021-STD-05 | C26: IA-ST-021-STD-05 | D26: C | Palet (4000037): 1 adet | Shrink film (4001177): 0.597 kg | E26: IA-ST-CFG-0025 | F26: 1 | G26: 7 | H26: 30.983 | I26: REV00 CURRENT EVIDENCE BASIS — ARTICLE 5 ASSESSMENT BASIS | J26: PENDING - DRAWING | K26: PENDING - PHOTOGRAPHS | L26: Rev.00 | M26: =HYPERLINK("01_STARTER/ST-021-STD-05/01_Technical_File.docx","Open")
A27: IA-PPWR-TF-ST-024-EUR-01-R00 | B27: ST-024-EUR-01 | C27: IA-ST-024-EUR-01 | D27: TRACTOR | Palet (4000038): 1 adet | Honeycomb (4001186): 2 adet | E27: IA-ST-CFG-0035 | F27: 1 | G27: 8 | H27: 36.726 | I27: REV00 CURRENT EVIDENCE BASIS — ARTICLE 5 ASSESSMENT BASIS | J27: PENDING - DRAWING | K27: PENDING - PHOTOGRAPHS | L27: Rev.00 | M27: =HYPERLINK("01_STARTER/ST-024-EUR-01/01_Technical_File.docx","Open")
A28: IA-PPWR-TF-ST-024-EUR-02-R00 | B28: ST-024-EUR-02 | C28: IA-ST-024-EUR-02 | D28: A | A TİPİ VAKUM PVC PVC üst kapak (4000720): 24 adet | E28: IA-ST-CFG-0037 | F28: 1 | G28: 9 | H28: 32.84464 | I28: REV00 CURRENT EVIDENCE BASIS — ARTICLE 5 ASSESSMENT BASIS | J28: PENDING - DRAWING | K28: PENDING - PHOTOGRAPHS | L28: Rev.00 | M28: =HYPERLINK("01_STARTER/ST-024-EUR-02/01_Technical_File.docx","Open")
